Workbook
Name SegmentaciónDeDatos_AÑO: #N/A
Name SegmentaciónDeDatos_AÑO1: #N/A
Name SegmentaciónDeDatos_MES: #N/A
Name SegmentaciónDeDatos_MES1: #N/A

Sheet Ene
A2: DETALLE DE VENTAS 2026
E3: COSTO SIT UNITARIO | H3: COSTO SIT CANTIDAD
A4: GRUPO | B4: REF. | C4: DESCRIPCION | D4: CANT | E4: CUMAT | F4: CUMO | G4: CUNago | H4: CTMAT | I4: CTMO | J4: CTSIT | K4: %PART | L4: CIFU | M4: MOU | N4: CTU | O4: CT | P4: PUV | Q4: PRECIOTOT | R4: %CTO | S4: %Part.
A5: =VLOOKUP(B5,Grupos!$A$2:$B$619,2,FALSE) -> ACCESORIOS | B5: BN-08 | C5: BANDEJA PARA INTERIOR *I-8P* | D5: 1 | E5: 1216.9 | F5: 76.52 | G5: =E5+F5 -> 1293.42 | H5: =E5*D5 -> 1216.9 | I5: =F5*D5 -> 76.52 | J5: =G5*D5 -> 1293.42 | K5: =J5/$J$293 -> 9.7176893e-07 | L5: =$K$364*K5/D5 -> 251.39558 | M5: =F5*$M$363 -> 410.93762 | N5: =G5+L5+M5 -> 1955.7532 | O5: =N5*D5 -> 1955.7532 | P5: =Q5/D5 -> 12075 | Q5: 12075 | R5: =O5/Q5 -> 0.16196714
A6: =VLOOKUP(B6,Grupos!$A$2:$B$619,2,FALSE) -> ACCESORIOS | B6: BN-12 | C6: BANDEJA PARA INTERIOR *I-12P,I-212,I-312 | D6: 4 | E6: 1547.34 | F6: 77.82 | G6: =E6+F6 -> 1625.16 | H6: =E6*D6 -> 6189.36 | I6: =F6*D6 -> 311.28 | J6: =G6*D6 -> 6500.64 | K6: =J6/$J$293 -> 4.8840438e-06 | L6: =$K$364*K6/D6 -> 315.87422 | M6: =F6*$M$363 -> 417.91904 | N6: =G6+L6+M6 -> 2358.9533 | O6: =N6*D6 -> 9435.8131 | P6: =Q6/D6 -> 9492 | Q6: 37968 | R6: =O6/Q6 -> 0.24852015
A7: =VLOOKUP(B7,Grupos!$A$2:$B$619,2,FALSE) -> ACCESORIOS | B7: BN-24 | C7: BANDEJA PARA INTERIOR *I-224,I-324* | D7: 1 | E7: 2376.63 | F7: 89.86 | G7: =E7+F7 -> 2466.49 | H7: =E7*D7 -> 2376.63 | I7: =F7*D7 -> 89.86 | J7: =G7*D7 -> 2466.49 | K7: =J7/$J$293 -> 1.8531168e-06 | L7: =$K$364*K7/D7 -> 479.39932 | M7: =F7*$M$363 -> 482.57781 | N7: =G7+L7+M7 -> 3428.4671 | O7: =N7*D7 -> 3428.4671 | P7: =Q7/D7 -> 15664 | Q7: 15664 | R7: =O7/Q7 -> 0.21887558
A8: =VLOOKUP(B8,Grupos!$A$2:$B$619,2,FALSE) -> ACCESORIOS | B8: CHAPA-1 | C8: CHAPA GAVETA (TRPs) | D8: 3 | E8: 3200 | F8: 0 | G8: =E8+F8 -> 3200 | H8: =E8*D8 -> 9600 | I8: =F8*D8 -> 0 | J8: =G8*D8 -> 9600 | K8: =J8/$J$293 -> 7.2126469e-06 | L8: =$K$364*K8/D8 -> 621.96799 | M8: =F8*$M$363 -> 0 | N8: =G8+L8+M8 -> 3821.968 | O8: =N8*D8 -> 11465.904 | P8: =Q8/D8 -> 13987.5 | Q8: 41962.5 | R8: =O8/Q8 -> 0.27324168
A9: =VLOOKUP(B9,Grupos!$A$2:$B$619,2,FALSE) -> ACCESORIOS | B9: FLETES | C9: VALOR FLETES MERCANCIA | D9: 3 | E9: 0 | F9: 0 | G9: =E9+F9 -> 0 | H9: =E9*D9 -> 0 | I9: =F9*D9 -> 0 | J9: =G9*D9 -> 0 | K9: =J9/$J$293 -> 0 | L9: =$K$364*K9/D9 -> 0 | M9: =F9*$M$363 -> 0 | N9: =G9+L9+M9 -> 0 | O9: =N9*D9 -> 0 | P9: =Q9/D9 -> 147333.33 | Q9: 442000 | R9: =O9/Q9 -> 0
A10: =VLOOKUP(B10,Grupos!$A$2:$B$619,2,FALSE) -> ACCESORIOS | B10: GRAPAM12-D | C10: GRAPA METALICA 1/2" DOBLE | D10: 39600 | E10: 59.89 | F10: 34.71 | G10: =E10+F10 -> 94.6 | H10: =E10*D10 -> 2371644 | I10: =F10*D10 -> 1374516 | J10: =G10*D10 -> 3746160 | K10: =J10/$J$293 -> 0.0028145551 | L10: =$K$364*K10/D10 -> 18.386929 | M10: =F10*$M$363 -> 186.40414 | N10: =G10+L10+M10 -> 299.39107 | O10: =N10*D10 -> 11855886 | P10: =Q10/D10 -> 126.09091 | Q10: 4993200.2 | R10: =O10/Q10 -> 2.3744064
A11: =VLOOKUP(B11,Grupos!$A$2:$B$619,2,FALSE) -> ACCESORIOS | B11: GRAPAM12-S | C11: GRAPA METALICA 1/2" SENCILLA | D11: 2400 | E11: 43.39 | F11: 43.22 | G11: =E11+F11 -> 86.61 | H11: =E11*D11 -> 104136 | I11: =F11*D11 -> 103728 | J11: =G11*D11 -> 207864 | K11: =J11/$J$293 -> 0.00015617184 | L11: =$K$364*K11/D11 -> 16.833952 | M11: =F11*$M$363 -> 232.10564 | N11: =G11+L11+M11 -> 335.54959 | O11: =N11*D11 -> 805319.03 | P11: =Q11/D11 -> 102.50001 | Q11: 246000.02 | R11: =O11/Q11 -> 3.2736543
A12: =VLOOKUP(B12,Grupos!$A$2:$B$619,2,FALSE) -> ACCESORIOS | B12: NEUTRO12 | C12: NEUTRO DE 12 CIRCUITOS | D12: 15 | E12: 2166.94 | F12: 0 | G12: =E12+F12 -> 2166.94 | H12: =E12*D12 -> 32504.1 | I12: =F12*D12 -> 0 | J12: =G12*D12 -> 32504.1 | K12: =J12/$J$293 -> 2.4420895e-05 | L12: =$K$364*K12/D12 -> 421.17729 | M12: =F12*$M$363 -> 0 | N12: =G12+L12+M12 -> 2588.1173 | O12: =N12*D12 -> 38821.759 | P12: =Q12/D12 -> 16952 | Q12: 254280 | R12: =O12/Q12 -> 0.15267327
A13: =VLOOKUP(B13,Grupos!$A$2:$B$619,2,FALSE) -> ACCESORIOS | B13: NEUTRO18 | C13: NEUTRO DE 18 CIRCUITOS | D13: 5 | E13: 3042.06 | F13: 0 | G13: =E13+F13 -> 3042.06 | H13: =E13*D13 -> 15210.3 | I13: =F13*D13 -> 0 | J13: =G13*D13 -> 15210.3 | K13: =J13/$J$293 -> 1.1427763e-05 | L13: =$K$364*K13/D13 -> 591.26998 | M13: =F13*$M$363 -> 0 | N13: =G13+L13+M13 -> 3633.33 | O13: =N13*D13 -> 18166.65 | P13: =Q13/D13 -> 19250 | Q13: 96250 | R13: =O13/Q13 -> 0.18874441
A14: =VLOOKUP(B14,Grupos!$A$2:$B$619,2,FALSE) -> ACCESORIOS | B14: NEUTRO24R | C14: NEUTRO DE 24 CIRCUITOS REFORZADO | D14: 13 | E14: 9036.65 | F14: 0 | G14: =E14+F14 -> 9036.65 | H14: =E14*D14 -> 117476.45 | I14: =F14*D14 -> 0 | J14: =G14*D14 -> 117476.45 | K14: =J14/$J$293 -> 8.8262099e-05 | L14: =$K$364*K14/D14 -> 1756.4085 | M14: =F14*$M$363 -> 0 | N14: =G14+L14+M14 -> 10793.058 | O14: =N14*D14 -> 140309.76 | P14: =Q14/D14 -> 38300.577 | Q14: 497907.5 | R14: =O14/Q14 -> 0.28179885
A15: =VLOOKUP(B15,Grupos!$A$2:$B$619,2,FALSE) -> ACCESORIOS | B15: NEUTRO42R | C15: NEUTRO DE 42 CIRCUITOS REFORZADO | D15: 2 | E15: 14590.87 | F15: 0 | G15: =E15+F15 -> 14590.87 | H15: =E15*D15 -> 29181.74 | I15: =F15*D15 -> 0 | J15: =G15*D15 -> 29181.74 | K15: =J15/$J$293 -> 2.1924748e-05 | L15: =$K$364*K15/D15 -> 2835.9544 | M15: =F15*$M$363 -> 0 | N15: =G15+L15+M15 -> 17426.824 | O15: =N15*D15 -> 34853.649 | P15: =Q15/D15 -> 85125 | Q15: 170250 | R15: =O15/Q15 -> 0.2047204
A16: =VLOOKUP(B16,Grupos!$A$2:$B$619,2,FALSE) -> ACCESORIOS | B16: NEUTRO6 | C16: NEUTRO DE 6 CIRCUITOS | D16: 10 | E16: 1229.39 | F16: 0 | G16: =E16+F16 -> 1229.39 | H16: =E16*D16 -> 12293.9 | I16: =F16*D16 -> 0 | J16: =G16*D16 -> 12293.9 | K16: =J16/$J$293 -> 9.2366208e-06 | L16: =$K$364*K16/D16 -> 238.95038 | M16: =F16*$M$363 -> 0 | N16: =G16+L16+M16 -> 1468.3404 | O16: =N16*D16 -> 14683.404 | P16: =Q16/D16 -> 6776 | Q16: 67760 | R16: =O16/Q16 -> 0.21669722
... A33: =VLOOKUP(B33,Grupos!$A$2:$B$619,2,FALSE) -> ACCESORIOS | B33: TIERRA8ALET | C33: TIERRA 8 CIRCUITOS ALET | D33: 150 | E33: 1201 | F33: 0 | G33: =E33+F33 -> 1201 | H33: =E33*D33 -> 180150 | I33: =F33*D33 -> 0 | J33: =G33*D33 -> 180150 | K33: =J33/$J$293 -> 0.00013534983 | L33: =$K$364*K33/D33 -> 233.43236 | M33: =F33*$M$363 -> 0 | N33: =G33+L33+M33 -> 1434.4324 | O33: =N33*D33 -> 215164.85 | P33: =Q33/D33 -> 9240.0004 | Q33: 1386000.1 | R33: =O33/Q33 -> 0.15524159
A34: Total ACCESORIOS | D34: =SUBTOTAL(9,D5:D33) -> 43103 | H34: =SUBTOTAL(9,H5:H33) -> 3330960.9 | I34: =SUBTOTAL(9,I5:I33) -> 1479744.8 | J34: =SUBTOTAL(9,J5:J33) -> 4810705.7 | O34: =SUBTOTAL(9,O5:O33) -> 13692456 | Q34: =SUBTOTAL(9,Q5:Q33) -> 10984624 | R34: =O34/Q34 -> 1.2465111 | S34: =Q34/$Q$293 -> 0.0033463018
A35: =VLOOKUP(B35,Grupos!$A$2:$B$619,2,FALSE) -> ADAPTADORES | B35: ACAMPANA12 | C35: ADAPTADOR CAMPANA 1/2" | D35: 11200 | E35: 14.92 | F35: 4.79 | G35: =E35+F35 -> 19.71 | H35: =E35*D35 -> 167104 | I35: =F35*D35 -> 53648 | J35: =G35*D35 -> 220752 | K35: =J35/$J$293 -> 0.00016585481 | L35: =$K$364*K35/D35 -> 3.8309341 | M35: =F35*$M$363 -> 25.723878 | N35: =G35+L35+M35 -> 49.264813 | O35: =N35*D35 -> 551765.9 | P35: =Q35/D35 -> 87.857146 | Q35: 984000.04 | R35: =O35/Q35 -> 0.56073768
A36: =VLOOKUP(B36,Grupos!$A$2:$B$619,2,FALSE) -> ADAPTADORES | B36: ACAMPANA34 | C36: ADAPTADOR CAMPANA 3/4" | D36: 3000 | E36: 19.99 | F36: 5.28 | G36: =E36+F36 -> 25.27 | H36: =E36*D36 -> 59970 | I36: =F36*D36 -> 15840 | J36: =G36*D36 -> 75810 | K36: =J36/$J$293 -> 5.6957371e-05 | L36: =$K$364*K36/D36 -> 4.9116035 | M36: =F36*$M$363 -> 28.35534 | N36: =G36+L36+M36 -> 58.536943 | O36: =N36*D36 -> 175610.83 | P36: =Q36/D36 -> 114 | Q36: 341999.99 | R36: =O36/Q36 -> 0.51348198
A37: =VLOOKUP(B37,Grupos!$A$2:$B$619,2,FALSE) -> ADAPTADORES | B37: ADAPTER12 | C37: ADAPTADOR TERMINAL 1/2" | D37: 552000 | E37: 25.93 | F37: 11.01 | G37: =E37+F37 -> 36.94 | H37: =E37*D37 -> 14313360 | I37: =F37*D37 -> 6077520 | J37: =G37*D37 -> 20390880 | K37: =J37/$J$293 -> 0.015320023 | L37: =$K$364*K37/D37 -> 7.179843 | M37: =F37*$M$363 -> 59.127328 | N37: =G37+L37+M37 -> 103.24717 | O37: =N37*D37 -> 56992439 | P37: =Q37/D37 -> 106.51957 | Q37: 58798802 | R37: =O37/Q37 -> 0.96927891
A38: =VLOOKUP(B38,Grupos!$A$2:$B$619,2,FALSE) -> ADAPTADORES | B38: ADAPTER34 | C38: ADAPTADOR TERMINAL 3/4" | D38: 192800 | E38: 39.89 | F38: 11.25 | G38: =E38+F38 -> 51.14 | H38: =E38*D38 -> 7690792 | I38: =F38*D38 -> 2169000 | J38: =G38*D38 -> 9859792 | K38: =J38/$J$293 -> 0.0074078331 | L38: =$K$364*K38/D38 -> 9.939826 | M38: =F38*$M$363 -> 60.416207 | N38: =G38+L38+M38 -> 121.49603 | O38: =N38*D38 -> 23424435 | P38: =Q38/D38 -> 142.29046 | Q38: 27433601 | R38: =O38/Q38 -> 0.85385929
A39: Total ADAPTADORES | D39: =SUBTOTAL(9,D35:D38) -> 759000 | H39: =SUBTOTAL(9,H35:H38) -> 22231226 | I39: =SUBTOTAL(9,I35:I38) -> 8316008 | J39: =SUBTOTAL(9,J35:J38) -> 30547234 | O39: =SUBTOTAL(9,O35:O38) -> 81144250 | Q39: =SUBTOTAL(9,Q35:Q38) -> 87558403 | R39: =O39/Q39 -> 0.92674429 | S39: =Q39/$Q$293 -> 0.02667336
A40: =VLOOKUP(B40,Grupos!$A$2:$B$619,2,FALSE) -> CAJAS ARRANCADORAS | B40: CA-30 | C40: CAJA ARRANCADOR Y CONTROL INDUSTRIAL 30X20X16 | D40: 3 | E40: 30739.86 | F40: 5164.81 | G40: =E40+F40 -> 35904.67 | H40: =E40*D40 -> 92219.58 | I40: =F40*D40 -> 15494.43 | J40: =G40*D40 -> 107714.01 | K40: =J40/$J$293 -> 8.0927408e-05 | L40: =$K$364*K40/D40 -> 6978.6111 | M40: =F40*$M$363 -> 27736.732 | N40: =G40+L40+M40 -> 70620.013 | O40: =N40*D40 -> 211860.04 | P40: =Q40/D40 -> 102543 | Q40: 307629 | R40: =O40/Q40 -> 0.68868682
A41: =VLOOKUP(B41,Grupos!$A$2:$B$619,2,FALSE) -> CAJAS ARRANCADORAS | B41: CA-70 | C41: CAJA ARRANCADOR Y CONTROL INDUSTRIAL 70X50X25 | D41: 7 | E41: 80513.68 | F41: 8176.17 | G41: =E41+F41 -> 88689.85 | H41: =E41*D41 -> 563595.76 | I41: =F41*D41 -> 57233.19 | J41: =G41*D41 -> 620828.95 | K41: =J41/$J$293 -> 0.00046643958 | L41: =$K$364*K41/D41 -> 17238.202 | M41: =F41*$M$363 -> 43908.727 | N41: =G41+L41+M41 -> 149836.78 | O41: =N41*D41 -> 1048857.5 | P41: =Q41/D41 -> 325214.87 | Q41: 2276504.1 | R41: =O41/Q41 -> 0.46073164
A42: =VLOOKUP(B42,Grupos!$A$2:$B$619,2,FALSE) -> CAJAS ARRANCADORAS | B42: CA-80 | C42: CAJA ARRANCADOR Y CONTROL INDUSTRIAL 80X50X25 | D42: 5 | E42: 86707.31 | F42: 10954.65 | G42: =E42+F42 -> 97661.96 | H42: =E42*D42 -> 433536.55 | I42: =F42*D42 -> 54773.25 | J42: =G42*D42 -> 488309.8 | K42: =J42/$J$293 -> 0.00036687564 | L42: =$K$364*K42/D42 -> 18982.067 | M42: =F42*$M$363 -> 58830.08 | N42: =G42+L42+M42 -> 175474.11 | O42: =N42*D42 -> 877370.54 | P42: =Q42/D42 -> 322411 | Q42: 1612055 | R42: =O42/Q42 -> 0.54425596
A43: =VLOOKUP(B43,Grupos!$A$2:$B$619,2,FALSE) -> CAJAS ARRANCADORAS | B43: CA-90 | C43: CAJA ARRANCADOR Y CONTROL INDUSTRIAL 90X50X25 | D43: 2 | E43: 97632.57 | F43: 6348.31 | G43: =E43+F43 -> 103980.88 | H43: =E43*D43 -> 195265.14 | I43: =F43*D43 -> 12696.62 | J43: =G43*D43 -> 207961.76 | K43: =J43/$J$293 -> 0.00015624528 | L43: =$K$364*K43/D43 -> 20210.244 | M43: =F43*$M$363 -> 34092.517 | N43: =G43+L43+M43 -> 158283.64 | O43: =N43*D43 -> 316567.28 | P43: =Q43/D43 -> 359078.77 | Q43: 718157.53 | R43: =O43/Q43 -> 0.44080479
A44: Total CAJAS ARRANCADORAS | D44: =SUBTOTAL(9,D40:D43) -> 17 | H44: =SUBTOTAL(9,H40:H43) -> 1284617 | I44: =SUBTOTAL(9,I40:I43) -> 140197.49 | J44: =SUBTOTAL(9,J40:J43) -> 1424814.5 | O44: =SUBTOTAL(9,O40:O43) -> 2454655.3 | Q44: =SUBTOTAL(9,Q40:Q43) -> 4914345.6 | R44: =O44/Q44 -> 0.49948773 | S44: =Q44/$Q$293 -> 0.001497082
A45: =VLOOKUP(B45,Grupos!$A$2:$B$619,2,FALSE) -> CAJAS EMPALME | B45: CE13-13-8B | C45: CAJA DE EMPALME 13X13X8 BLANCA | D45: 72 | E45: 3093.28 | F45: 1065.47 | G45: =E45+F45 -> 4158.75 | H45: =E45*D45 -> 222716.16 | I45: =F45*D45 -> 76713.84 | J45: =G45*D45 -> 299430 | K45: =J45/$J$293 -> 0.00022496696 | L45: =$K$364*K45/D45 -> 808.31543 | M45: =F45*$M$363 -> 5721.925 | N45: =G45+L45+M45 -> 10688.99 | O45: =N45*D45 -> 769607.31 | P45: =Q45/D45 -> 12158.25 | Q45: 875394.01 | R45: =O45/Q45 -> 0.87915533
A46: =VLOOKUP(B46,Grupos!$A$2:$B$619,2,FALSE) -> CAJAS EMPALME | B46: CE15-15-10B | C46: CAJA DE EMPALME 15X15X10 BLANCA | D46: 1260 | E46: 4183.02 | F46: 784.88 | G46: =E46+F46 -> 4967.9 | H46: =E46*D46 -> 5270605.2 | I46: =F46*D46 -> 988948.8 | J46: =G46*D46 -> 6259554 | K46: =J46/$J$293 -> 0.0047029117 | L46: =$K$364*K46/D46 -> 965.58587 | M46: =F46*$M$363 -> 4215.0642 | N46: =G46+L46+M46 -> 10148.55 | O46: =N46*D46 -> 12787173 | P46: =Q46/D46 -> 13611.714 | Q46: 17150760 | R46: =O46/Q46 -> 0.74557473
A47: =VLOOKUP(B47,Grupos!$A$2:$B$619,2,FALSE) -> CAJAS EMPALME | B47: CE20-15-10B | C47: CAJA DE EMPALME 20X15X10 BLANCA | D47: 44 | E47: 5073.7 | F47: 592.66 | G47: =E47+F47 -> 5666.36 | H47: =E47*D47 -> 223242.8 | I47: =F47*D47 -> 26077.04 | J47: =G47*D47 -> 249319.84 | K47: =J47/$J$293 -> 0.00018731833 | L47: =$K$364*K47/D47 -> 1101.342 | M47: =F47*$M$363 -> 3182.7795 | N47: =G47+L47+M47 -> 9950.4816 | O47: =N47*D47 -> 437821.19 | P47: =Q47/D47 -> 16372.75 | Q47: 720401.02 | R47: =O47/Q47 -> 0.60774649
A48: =VLOOKUP(B48,Grupos!$A$2:$B$619,2,FALSE) -> CAJAS EMPALME | B48: CE20-20-10B | C48: CAJA DE EMPALME 20X20X10 BLANCA | D48: 1740 | E48: 6127.68 | F48: 823.65 | G48: =E48+F48 -> 6951.33 | H48: =E48*D48 -> 10662163 | I48: =F48*D48 -> 1433151 | J48: =G48*D48 -> 12095314 | K48: =J48/$J$293 -> 0.0090874198 | L48: =$K$364*K48/D48 -> 1351.0952 | M48: =F48*$M$363 -> 4423.2719 | N48: =G48+L48+M48 -> 12725.697 | O48: =N48*D48 -> 22142713 | P48: =Q48/D48 -> 18357.333 | Q48: 31941760 | R48: =O48/Q48 -> 0.69322145
A49: =VLOOKUP(B49,Grupos!$A$2:$B$619,2,FALSE) -> CAJAS EMPALME | B49: CE20-20-15B | C49: CAJA DE EMPALME 20X20X15 BLANCA | D49: 1221 | E49: 7494.34 | F49: 780.46 | G49: =E49+F49 -> 8274.8 | H49: =E49*D49 -> 9150589.1 | I49: =F49*D49 -> 952941.66 | J49: =G49*D49 -> 10103531 | K49: =J49/$J$293 -> 0.0075909583 | L49: =$K$364*K49/D49 -> 1608.3315 | M49: =F49*$M$363 -> 4191.3274 | N49: =G49+L49+M49 -> 14074.459 | O49: =N49*D49 -> 17184914 | P49: =Q49/D49 -> 23593.192 | Q49: 28807288 | R49: =O49/Q49 -> 0.59654746
A50: =VLOOKUP(B50,Grupos!$A$2:$B$619,2,FALSE) -> CAJAS EMPALME | B50: CE25-20-10B | C50: CAJA DE EMPALME 25X20X10 BLANCA | D50: 18 | E50: 7089.89 | F50: 482.92 | G50: =E50+F50 -> 7572.81 | H50: =E50*D50 -> 127618.02 | I50: =F50*D50 -> 8692.56 | J50: =G50*D50 -> 136310.58 | K50: =J50/$J$293 -> 0.00010241251 | L50: =$K$364*K50/D50 -> 1471.8892 | M50: =F50*$M$363 -> 2593.4395 | N50: =G50+L50+M50 -> 11638.139 | O50: =N50*D50 -> 209486.5 | P50: =Q50/D50 -> 25256.002 | Q50: 454608.03 | R50: =O50/Q50 -> 0.46080686
A51: =VLOOKUP(B51,Grupos!$A$2:$B$619,2,FALSE) -> CAJAS EMPALME | B51: CE25-25-10B | C51: CAJA DE EMPALME 25X25X10 BLANCA | D51: 795 | E51: 8428.08 | F51: 647.97 | G51: =E51+F51 -> 9076.05 | H51: =E51*D51 -> 6700323.6 | I51: =F51*D51 -> 515136.15 | J51: =G51*D51 -> 7215459.7 | K51: =J51/$J$293 -> 0.0054211003 | L51: =$K$364*K51/D51 -> 1764.0664 | M51: =F51*$M$363 -> 3479.8124 | N51: =G51+L51+M51 -> 14319.929 | O51: =N51*D51 -> 11384343 | P51: =Q51/D51 -> 27317.187 | Q51: 21717164 | R51: =O51/Q51 -> 0.5242095
A52: =VLOOKUP(B52,Grupos!$A$2:$B$619,2,FALSE) -> CAJAS EMPALME | B52: CE25-25-15B | C52: CAJA DE EMPALME 25X25X15 BLANCA | D52: 528 | E52: 10016.57 | F52: 648.25 | G52: =E52+F52 -> 10664.82 | H52: =E52*D52 -> 5288749 | I52: =F52*D52 -> 342276 | J52: =G52*D52 -> 5631025 | K52: =J52/$J$293 -> 0.0042306869 | L52: =$K$364*K52/D52 -> 2072.8677 | M52: =F52*$M$363 -> 3481.3161 | N52: =G52+L52+M52 -> 16219.004 | O52: =N52*D52 -> 8563634 | P52: =Q52/D52 -> 31732.852 | Q52: 16754946 | R52: =O52/Q52 -> 0.51111081
A53: =VLOOKUP(B53,Grupos!$A$2:$B$619,2,FALSE) -> CAJAS EMPALME | B53: CE30-30-10B | C53: CAJA DE EMPALME 30X30X10 BLANCA | D53: 1230 | E53: 11060.96 | F53: 596.56 | G53: =E53+F53 -> 11657.52 | H53: =E53*D53 -> 13604981 | I53: =F53*D53 -> 733768.8 | J53: =G53*D53 -> 14338750 | K53: =J53/$J$293 -> 0.010772952 | L53: =$K$364*K53/D53 -> 2265.8138 | M53: =F53*$M$363 -> 3203.7238 | N53: =G53+L53+M53 -> 17127.058 | O53: =N53*D53 -> 21066281 | P53: =Q53/D53 -> 33475.573 | Q53: 41174955 | R53: =O53/Q53 -> 0.51162851
A54: =VLOOKUP(B54,Grupos!$A$2:$B$619,2,FALSE) -> CAJAS EMPALME | B54: CE30-30-15B | C54: CAJA DE EMPALME 30X30X15 BLANCA | D54: 1764 | E54: 12773.82 | F54: 721.56 | G54: =E54+F54 -> 13495.38 | H54: =E54*D54 -> 22533018 | I54: =F54*D54 -> 1272831.8 | J54: =G54*D54 -> 23805850 | K54: =J54/$J$293 -> 0.017885749 | L54: =$K$364*K54/D54 -> 2623.0295 | M54: =F54*$M$363 -> 3875.015 | N54: =G54+L54+M54 -> 19993.424 | O54: =N54*D54 -> 35268401 | P54: =Q54/D54 -> 39262.814 | Q54: 69259603 | R54: =O54/Q54 -> 0.50922037
A55: =VLOOKUP(B55,Grupos!$A$2:$B$619,2,FALSE) -> CAJAS EMPALME | B55: CE30-30-20B | C55: CAJA DE EMPALME 30X30X20 BLANCA | D55: 90 | E55: 16238.13 | F55: 1508.32 | G55: =E55+F55 -> 17746.45 | H55: =E55*D55 -> 1461431.7 | I55: =F55*D55 -> 135748.8 | J55: =G55*D55 -> 1597180.5 | K55: =J55/$J$293 -> 0.0011999895 | L55: =$K$364*K55/D55 -> 3449.2887 | M55: =F55*$M$363 -> 8100.1754 | N55: =G55+L55+M55 -> 29295.914 | O55: =N55*D55 -> 2636632.3 | P55: =Q55/D55 -> 47879.999 | Q55: 4309199.9 | R55: =O55/Q55 -> 0.61186121
A56: =VLOOKUP(B56,Grupos!$A$2:$B$619,2,FALSE) -> CAJAS EMPALME | B56: CE40-40-15B | C56: CAJA DE EMPALME 40X40X15 BLANCA | D56: 761 | E56: 20258.69 | F56: 1240.45 | G56: =E56+F56 -> 21499.14 | H56: =E56*D56 -> 15416863 | I56: =F56*D56 -> 943982.45 | J56: =G56*D56 -> 16360846 | K56: =J56/$J$293 -> 0.012292188 | L56: =$K$364*K56/D56 -> 4178.6803 | M56: =F56*$M$363 -> 6661.6253 | N56: =G56+L56+M56 -> 32339.446 | O56: =N56*D56 -> 24610318 | P56: =Q56/D56 -> 59300.715 | Q56: 45127844 | R56: =O56/Q56 -> 0.54534664
... A62: =VLOOKUP(B62,Grupos!$A$2:$B$619,2,FALSE) -> CAJAS EMPALME | B62: CI-BU | C62: CAJA INDUSTRIAL BREAKER UNIVERSAL 100 AMP | D62: 70 | E62: 9059.16 | F62: 636.21 | G62: =E62+F62 -> 9695.37 | H62: =E62*D62 -> 634141.2 | I62: =F62*D62 -> 44534.7 | J62: =G62*D62 -> 678675.9 | K62: =J62/$J$293 -> 0.000509901 | L62: =$K$364*K62/D62 -> 1884.4406 | M62: =F62*$M$363 -> 3416.6574 | N62: =G62+L62+M62 -> 14996.468 | O62: =N62*D62 -> 1049752.8 | P62: =Q62/D62 -> 36925.713 | Q62: 2584799.9 | R62: =O62/Q62 -> 0.40612534
...

Sheet Ene PUV lista
A2: DETALLE DE VENTAS 2026
E3: COSTO SIT UNITARIO | H3: COSTO SIT CANTIDAD
A4: GRUPO | B4: REF. | C4: DESCRIPCION | D4: CANT | E4: CUMAT | F4: CUMO | G4: CUNago | H4: CTMAT | I4: CTMO | J4: CTSIT | K4: %PART | L4: CIFU | M4: MOU | N4: CTU | O4: CT | P4: PUV | Q4: PU-LISTA | R4: DCTO PIE FACT | S4: % DCTO | T4: PRECIOTOT | U4: %CTO | V4: %Part.
A5: =VLOOKUP(B5,Grupos!$A$2:$B$619,2,FALSE) -> ACCESORIOS | B5: BN-08 | C5: BANDEJA PARA INTERIOR *I-8P* | D5: 1 | E5: 1216.9 | F5: 76.52 | G5: =E5+F5 -> 1293.42 | H5: =E5*D5 -> 1216.9 | I5: =F5*D5 -> 76.52 | J5: =G5*D5 -> 1293.42 | K5: =J5/$J$264 -> 9.7176893e-07 | L5: 251.39558 | M5: 410.93762 | N5: =G5+L5+M5 -> 1955.7532 | O5: =N5*D5 -> 1955.7532 | P5: =T5/D5 -> 12075 | Q5: 16100 | R5: =Q5-P5 -> 4025 | S5: =R5/Q5 -> 0.25 | T5: 12075 | U5: =O5/T5 -> 0.16196714
A6: =VLOOKUP(B6,Grupos!$A$2:$B$619,2,FALSE) -> ACCESORIOS | B6: BN-12 | C6: BANDEJA PARA INTERIOR *I-12P,I-212,I-312 | D6: 4 | E6: 1547.34 | F6: 77.82 | G6: =E6+F6 -> 1625.16 | H6: =E6*D6 -> 6189.36 | I6: =F6*D6 -> 311.28 | J6: =G6*D6 -> 6500.64 | K6: =J6/$J$264 -> 4.8840438e-06 | L6: 315.87422 | M6: 417.91904 | N6: =G6+L6+M6 -> 2358.9533 | O6: =N6*D6 -> 9435.8131 | P6: =T6/D6 -> 9492 | Q6: 22600 | R6: =Q6-P6 -> 13108 | S6: =R6/Q6 -> 0.58 | T6: 37968 | U6: =O6/T6 -> 0.24852015
A7: =VLOOKUP(B7,Grupos!$A$2:$B$619,2,FALSE) -> ACCESORIOS | B7: BN-24 | C7: BANDEJA PARA INTERIOR *I-224,I-324* | D7: 1 | E7: 2376.63 | F7: 89.86 | G7: =E7+F7 -> 2466.49 | H7: =E7*D7 -> 2376.63 | I7: =F7*D7 -> 89.86 | J7: =G7*D7 -> 2466.49 | K7: =J7/$J$264 -> 1.8531168e-06 | L7: 479.39932 | M7: 482.57781 | N7: =G7+L7+M7 -> 3428.4671 | O7: =N7*D7 -> 3428.4671 | P7: =T7/D7 -> 15664 | Q7: 33600 | R7: =Q7-P7 -> 17936 | S7: =R7/Q7 -> 0.53380952 | T7: 15664 | U7: =O7/T7 -> 0.21887558
A8: =VLOOKUP(B8,Grupos!$A$2:$B$619,2,FALSE) -> ACCESORIOS | B8: CHAPA-1 | C8: CHAPA GAVETA (TRPs) | D8: 3 | E8: 3200 | F8: 0 | G8: =E8+F8 -> 3200 | H8: =E8*D8 -> 9600 | I8: =F8*D8 -> 0 | J8: =G8*D8 -> 9600 | K8: =J8/$J$264 -> 7.2126469e-06 | L8: 621.96799 | M8: 0 | N8: =G8+L8+M8 -> 3821.968 | O8: =N8*D8 -> 11465.904 | P8: =T8/D8 -> 13987.5 | Q8: 18650 | R8: =Q8-P8 -> 4662.5 | S8: =R8/Q8 -> 0.25 | T8: 41962.5 | U8: =O8/T8 -> 0.27324168
A9: =VLOOKUP(B9,Grupos!$A$2:$B$619,2,FALSE) -> ACCESORIOS | B9: FLETES | C9: VALOR FLETES MERCANCIA | D9: 3 | E9: 0 | F9: 0 | G9: =E9+F9 -> 0 | H9: =E9*D9 -> 0 | I9: =F9*D9 -> 0 | J9: =G9*D9 -> 0 | K9: =J9/$J$264 -> 0 | L9: 0 | M9: 0 | N9: =G9+L9+M9 -> 0 | O9: =N9*D9 -> 0 | P9: =T9/D9 -> 147333.33 | Q9: 0 | S9: 0 | T9: 442000 | U9: =O9/T9 -> 0
A10: =VLOOKUP(B10,Grupos!$A$2:$B$619,2,FALSE) -> ACCESORIOS | B10: GRAPAM12-D | C10: GRAPA METALICA 1/2" DOBLE | D10: 39600 | E10: 59.89 | F10: 34.71 | G10: =E10+F10 -> 94.6 | H10: =E10*D10 -> 2371644 | I10: =F10*D10 -> 1374516 | J10: =G10*D10 -> 3746160 | K10: =J10/$J$264 -> 0.0028145551 | L10: 18.386929 | M10: 186.40414 | N10: =G10+L10+M10 -> 299.39107 | O10: =N10*D10 -> 11855886 | P10: =T10/D10 -> 126.09091 | Q10: 300 | R10: =Q10-P10 -> 173.90909 | S10: =R10/Q10 -> 0.57969695 | T10: 4993200.2 | U10: =O10/T10 -> 2.3744064
A11: =VLOOKUP(B11,Grupos!$A$2:$B$619,2,FALSE) -> ACCESORIOS | B11: GRAPAM12-S | C11: GRAPA METALICA 1/2" SENCILLA | D11: 2400 | E11: 43.39 | F11: 43.22 | G11: =E11+F11 -> 86.61 | H11: =E11*D11 -> 104136 | I11: =F11*D11 -> 103728 | J11: =G11*D11 -> 207864 | K11: =J11/$J$264 -> 0.00015617184 | L11: 16.833952 | M11: 232.10564 | N11: =G11+L11+M11 -> 335.54959 | O11: =N11*D11 -> 805319.03 | P11: =T11/D11 -> 102.50001 | Q11: 250 | R11: =Q11-P11 -> 147.49999 | S11: =R11/Q11 -> 0.58999997 | T11: 246000.02 | U11: =O11/T11 -> 3.2736543
A12: =VLOOKUP(B12,Grupos!$A$2:$B$619,2,FALSE) -> ACCESORIOS | B12: NEUTRO12 | C12: NEUTRO DE 12 CIRCUITOS | D12: 15 | E12: 2166.94 | F12: 0 | G12: =E12+F12 -> 2166.94 | H12: =E12*D12 -> 32504.1 | I12: =F12*D12 -> 0 | J12: =G12*D12 -> 32504.1 | K12: =J12/$J$264 -> 2.4420895e-05 | L12: 421.17729 | M12: 0 | N12: =G12+L12+M12 -> 2588.1173 | O12: =N12*D12 -> 38821.759 | P12: =T12/D12 -> 16952 | Q12: 31200 | R12: =Q12-P12 -> 14248 | S12: =R12/Q12 -> 0.45666667 | T12: 254280 | U12: =O12/T12 -> 0.15267327
A13: =VLOOKUP(B13,Grupos!$A$2:$B$619,2,FALSE) -> ACCESORIOS | B13: NEUTRO18 | C13: NEUTRO DE 18 CIRCUITOS | D13: 5 | E13: 3042.06 | F13: 0 | G13: =E13+F13 -> 3042.06 | H13: =E13*D13 -> 15210.3 | I13: =F13*D13 -> 0 | J13: =G13*D13 -> 15210.3 | K13: =J13/$J$264 -> 1.1427763e-05 | L13: 591.26998 | M13: 0 | N13: =G13+L13+M13 -> 3633.33 | O13: =N13*D13 -> 18166.65 | P13: =T13/D13 -> 19250 | Q13: 43750 | R13: =Q13-P13 -> 24500 | S13: =R13/Q13 -> 0.56 | T13: 96250 | U13: =O13/T13 -> 0.18874441
A14: =VLOOKUP(B14,Grupos!$A$2:$B$619,2,FALSE) -> ACCESORIOS | B14: NEUTRO24R | C14: NEUTRO DE 24 CIRCUITOS REFORZADO | D14: 13 | E14: 9036.65 | F14: 0 | G14: =E14+F14 -> 9036.65 | H14: =E14*D14 -> 117476.45 | I14: =F14*D14 -> 0 | J14: =G14*D14 -> 117476.45 | K14: =J14/$J$264 -> 8.8262099e-05 | L14: 1756.4085 | M14: 0 | N14: =G14+L14+M14 -> 10793.058 | O14: =N14*D14 -> 140309.76 | P14: =T14/D14 -> 38300.577 | Q14: 69250 | R14: =Q14-P14 -> 30949.423 | S14: =R14/Q14 -> 0.44692308 | T14: 497907.5 | U14: =O14/T14 -> 0.28179885
A15: =VLOOKUP(B15,Grupos!$A$2:$B$619,2,FALSE) -> ACCESORIOS | B15: NEUTRO42R | C15: NEUTRO DE 42 CIRCUITOS REFORZADO | D15: 2 | E15: 14590.87 | F15: 0 | G15: =E15+F15 -> 14590.87 | H15: =E15*D15 -> 29181.74 | I15: =F15*D15 -> 0 | J15: =G15*D15 -> 29181.74 | K15: =J15/$J$264 -> 2.1924748e-05 | L15: 2835.9544 | M15: 0 | N15: =G15+L15+M15 -> 17426.824 | O15: =N15*D15 -> 34853.649 | P15: =T15/D15 -> 85125 | Q15: 113500 | R15: =Q15-P15 -> 28375 | S15: =R15/Q15 -> 0.25 | T15: 170250 | U15: =O15/T15 -> 0.2047204
A16: =VLOOKUP(B16,Grupos!$A$2:$B$619,2,FALSE) -> ACCESORIOS | B16: NEUTRO6 | C16: NEUTRO DE 6 CIRCUITOS | D16: 10 | E16: 1229.39 | F16: 0 | G16: =E16+F16 -> 1229.39 | H16: =E16*D16 -> 12293.9 | I16: =F16*D16 -> 0 | J16: =G16*D16 -> 12293.9 | K16: =J16/$J$264 -> 9.2366208e-06 | L16: 238.95038 | M16: 0 | N16: =G16+L16+M16 -> 1468.3404 | O16: =N16*D16 -> 14683.404 | P16: =T16/D16 -> 6776 | Q16: 15400 | R16: =Q16-P16 -> 8624 | S16: =R16/Q16 -> 0.56 | T16: 67760 | U16: =O16/T16 -> 0.21669722
A17: =VLOOKUP(B17,Grupos!$A$2:$B$619,2,FALSE) -> ACCESORIOS | B17: NEUTRO8 | C17: NEUTRO DE 8 CIRCUITOS | D17: 10 | E17: 1583.66 | F17: 0 | G17: =E17+F17 -> 1583.66 | H17: =E17*D17 -> 15836.6 | I17: =F17*D17 -> 0 | J17: =G17*D17 -> 15836.6 | K17: =J17/$J$264 -> 1.1898313e-05 | L17: 307.80807 | M17: 0 | N17: =G17+L17+M17 -> 1891.4681 | O17: =N17*D17 -> 18914.681 | P17: =T17/D17 -> 9680 | Q17: 22000 | R17: =Q17-P17 -> 12320 | S17: =R17/Q17 -> 0.56 | T17: 96800 | U17: =O17/T17 -> 0.19539959
A18: =VLOOKUP(B18,Grupos!$A$2:$B$619,2,FALSE) -> ACCESORIOS | B18: NEUTRO8ALET | C18: NEUTRO 8 CIRCUITOS ALET | D18: 150 | E18: 1185 | F18: 0 | G18: =E18+F18 -> 1185 | H18: =E18*D18 -> 177750 | I18: =F18*D18 -> 0 | J18: =G18*D18 -> 177750 | K18: =J18/$J$264 -> 0.00013354666 | L18: 230.32252 | M18: 0 | N18: =G18+L18+M18 -> 1415.3225 | O18: =N18*D18 -> 212298.38 | P18: =T18/D18 -> 9240.0004 | Q18: 22000 | R18: =Q18-P18 -> 12760 | S18: =R18/Q18 -> 0.57999998 | T18: 1386000.1 | U18: =O18/T18 -> 0.15317343
A19: =VLOOKUP(B19,Grupos!$A$2:$B$619,2,FALSE) -> ACCESORIOS | B19: PUERTA VISOR8 | C19: PUERTA VISOR PLASTICO TABLERO 8 DE 95 AMP | D19: 20 | E19: 1003 | F19: 0 | G19: =E19+F19 -> 1003 | H19: =E19*D19 -> 20060 | I19: =F19*D19 -> 0 | J19: =G19*D19 -> 20060 | K19: =J19/$J$264 -> 1.5071427e-05 | L19: 194.94809 | M19: 0 | N19: =G19+L19+M19 -> 1197.9481 | O19: =N19*D19 -> 23958.962 | P19: =T19/D19 -> 3006 | Q19: 8350 | R19: =Q19-P19 -> 5344 | S19: =R19/Q19 -> 0.64 | T19: 60120 | U19: =O19/T19 -> 0.39851899
A20: =VLOOKUP(B20,Grupos!$A$2:$B$619,2,FALSE) -> ACCESORIOS | B20: T1012P | C20: TORNILLO LAMINA 10 x1/2 | D20: 24 | E20: 60 | F20: 0 | G20: =E20+F20 -> 60 | H20: =E20*D20 -> 1440 | I20: =F20*D20 -> 0 | J20: =G20*D20 -> 1440 | K20: =J20/$J$264 -> 1.081897e-06 | L20: 11.6619 | M20: 0 | N20: =G20+L20+M20 -> 71.6619 | O20: =N20*D20 -> 1719.8856 | P20: =T20/D20 -> 220 | Q20: 220 | R20: =Q20-P20 -> 0 | S20: =R20/Q20 -> 0 | T20: 5280 | U20: =O20/T20 -> 0.32573591
A21: =VLOOKUP(B21,Grupos!$A$2:$B$619,2,FALSE) -> ACCESORIOS | B21: T10P | C21: TORNILLO LAMINA 10 x 1. 1/4 PUNTA GUIA | D21: 584 | E21: 84.21 | F21: 0 | G21: =E21+F21 -> 84.21 | H21: =E21*D21 -> 49178.64 | I21: =F21*D21 -> 0 | J21: =G21*D21 -> 49178.64 | K21: =J21/$J$264 -> 3.6948767e-05 | L21: 16.367476 | M21: 0 | N21: =G21+L21+M21 -> 100.57748 | O21: =N21*D21 -> 58737.246 | P21: =T21/D21 -> 300 | Q21: 300 | R21: =Q21-P21 -> 0 | S21: =R21/Q21 -> 0 | T21: 175200 | U21: =O21/T21 -> 0.33525825
... A77: =VLOOKUP(B77,Grupos!$A$2:$B$619,2,FALSE) -> CE 125 | B77: CE125LXB | C77: CAJA 12X12X5 TAPA DATOS BLANCA | D77: 780 | E77: 2141.44 | F77: 426.01 | G77: =E77+F77 -> 2567.45 | H77: =E77*D77 -> 1670323.2 | I77: =F77*D77 -> 332287.8 | J77: =G77*D77 -> 2002611 | K77: =J77/$J$264 -> 0.0015045965 | L77: 499.02241 | M77: 2287.8141 | N77: =G77+L77+M77 -> 5354.2865 | O77: =N77*D77 -> 4176343.5 | P77: =T77/D77 -> 5226 | Q77: 15400 | R77: =Q77-P77 -> 10174 | S77: =R77/Q77 -> 0.66064935 | T77: 4076280 | U77: =O77/T77 -> 1.0245477
A78: =VLOOKUP(B78,Grupos!$A$2:$B$619,2,FALSE) -> EXCEDENTES INDUSTRIALES | B78: EXARCHIVO | C78: EXCEDENTES INDUSTRIALES DE ARCHIVO | D78: 85 | E78: 0 | F78: 0 | G78: =E78+F78 -> 0 | H78: =E78*D78 -> 0 | I78: =F78*D78 -> 0 | J78: =G78*D78 -> 0 | K78: =J78/$J$264 -> 0 | L78: 0 | M78: 0 | N78: =G78+L78+M78 -> 0 | O78: =N78*D78 -> 0 | P78: =T78/D78 -> 739.41176 | Q78: 0 | S78: 0 | T78: 62850 | U78: =O78/T78 -> 0
A79: =VLOOKUP(B79,Grupos!$A$2:$B$619,2,FALSE) -> EXCEDENTES INDUSTRIALES | B79: EXBOLSASP | C79: EXCEDENTES BOLSAS PLASTICAS | D79: 18.65 | E79: 0 | F79: 0 | G79: =E79+F79 -> 0 | H79: =E79*D79 -> 0 | I79: =F79*D79 -> 0 | J79: =G79*D79 -> 0 | K79: =J79/$J$264 -> 0 | L79: 0 | M79: 0 | N79: =G79+L79+M79 -> 0 | O79: =N79*D79 -> 0 | P79: =T79/D79 -> 500 | Q79: 0 | S79: 0 | T79: 9325 | U79: =O79/T79 -> 0
A80: =VLOOKUP(B80,Grupos!$A$2:$B$619,2,FALSE) -> EXCEDENTES INDUSTRIALES | B80: EXCARTON | C80: EXCEDENTES INDUSTRIALES DE CATON | D80: 864 | E80: 0 | F80: 0 | G80: =E80+F80 -> 0 | H80: =E80*D80 -> 0 | I80: =F80*D80 -> 0 | J80: =G80*D80 -> 0 | K80: =J80/$J$264 -> 0 | L80: 0 | M80: 0 | N80: =G80+L80+M80 -> 0 | O80: =N80*D80 -> 0 | P80: =T80/D80 -> 300 | Q80: 0 | S80: 0 | T80: 259200 | U80: =O80/T80 -> 0
A81: =VLOOKUP(B81,Grupos!$A$2:$B$619,2,FALSE) -> EXCEDENTES INDUSTRIALES | B81: EXCEBARREDU | C81: EXCEDENTES INDUSTRIALES - BARREDURA PP | D81: 548.05 | E81: 0 | F81: 0 | G81: =E81+F81 -> 0 | H81: =E81*D81 -> 0 | I81: =F81*D81 -> 0 | J81: =G81*D81 -> 0 | K81: =J81/$J$264 -> 0 | L81: 0 | M81: 0 | N81: =G81+L81+M81 -> 0 | O81: =N81*D81 -> 0 | P81: =T81/D81 -> 500 | Q81: 0 | S81: 0 | T81: 274025 | U81: =O81/T81 -> 0
A82: =VLOOKUP(B82,Grupos!$A$2:$B$619,2,FALSE) -> EXCEDENTES INDUSTRIALES | B82: EXCEDENTES | C82: EXCEDENTES INDUSTRIALES MADEROS CORTOS | D82: 112 | E82: 0 | F82: 0 | G82: =E82+F82 -> 0 | H82: =E82*D82 -> 0 | I82: =F82*D82 -> 0 | J82: =G82*D82 -> 0 | K82: =J82/$J$264 -> 0 | L82: 0 | M82: 0 | N82: =G82+L82+M82 -> 0 | O82: =N82*D82 -> 0 | P82: =T82/D82 -> 500 | Q82: 0 | S82: 0 | T82: 56000 | U82: =O82/T82 -> 0
A83: =VLOOKUP(B83,Grupos!$A$2:$B$619,2,FALSE) -> EXCEDENTES INDUSTRIALES | B83: EXCEDENTESIN | C83: EXCEDENTES INDUSTRIALES MADEROS LARGOS | D83: 67 | E83: 0 | F83: 0 | G83: =E83+F83 -> 0 | H83: =E83*D83 -> 0 | I83: =F83*D83 -> 0 | J83: =G83*D83 -> 0 | K83: =J83/$J$264 -> 0 | L83: 0 | M83: 0 | N83: =G83+L83+M83 -> 0 | O83: =N83*D83 -> 0 | P83: =T83/D83 -> 1000 | Q83: 0 | S83: 0 | T83: 67000 | U83: =O83/T83 -> 0
A84: =VLOOKUP(B84,Grupos!$A$2:$B$619,2,FALSE) -> EXCEDENTES INDUSTRIALES | B84: EXCETORTAPOC | C84: EXCEDENTES INDUSTRIALES TORTA POLICARBONATO | D84: 292.5 | E84: 0 | F84: 0 | G84: =E84+F84 -> 0 | H84: =E84*D84 -> 0 | I84: =F84*D84 -> 0 | J84: =G84*D84 -> 0 | K84: =J84/$J$264 -> 0 | L84: 0 | M84: 0 | N84: =G84+L84+M84 -> 0 | O84: =N84*D84 -> 0 | P84: =T84/D84 -> 250 | Q84: 0 | S84: 0 | T84: 73125 | U84: =O84/T84 -> 0
A85: =VLOOKUP(B85,Grupos!$A$2:$B$619,2,FALSE) -> EXCEDENTES INDUSTRIALES | B85: EXCETORTAPOLIP | C85: EXCEDENTES INDUSTRIALES TORTA POLIPROPILENO | D85: 252.6 | E85: 0 | F85: 0 | G85: =E85+F85 -> 0 | H85: =E85*D85 -> 0 | I85: =F85*D85 -> 0 | J85: =G85*D85 -> 0 | K85: =J85/$J$264 -> 0 | L85: 0 | M85: 0 | N85: =G85+L85+M85 -> 0 | O85: =N85*D85 -> 0 | P85: =T85/D85 -> 250 | Q85: 0 | S85: 0 | T85: 63150 | U85: =O85/T85 -> 0
A86: =VLOOKUP(B86,Grupos!$A$2:$B$619,2,FALSE) -> EXCEDENTES INDUSTRIALES | B86: EXCINDUSTR | C86: EXCEDENTES INDUSTRIALES - REMOLIDO DE POLICARBONATO | D86: 156.85 | E86: 0 | F86: 0 | G86: =E86+F86 -> 0 | H86: =E86*D86 -> 0 | I86: =F86*D86 -> 0 | J86: =G86*D86 -> 0 | K86: =J86/$J$264 -> 0 | L86: 0 | M86: 0 | N86: =G86+L86+M86 -> 0 | O86: =N86*D86 -> 0 | P86: =T86/D86 -> 500 | Q86: 0 | S86: 0 | T86: 78425 | U86: =O86/T86 -> 0
A87: =VLOOKUP(B87,Grupos!$A$2:$B$619,2,FALSE) -> EXCEDENTES INDUSTRIALES | B87: EXCOSTALES | C87: EXCEDENTE DE PLASTICO COSTALES | D87: 909 | E87: 0 | F87: 0 | G87: =E87+F87 -> 0 | H87: =E87*D87 -> 0 | I87: =F87*D87 -> 0 | J87: =G87*D87 -> 0 | K87: =J87/$J$264 -> 0 | L87: 0 | M87: 0 | N87: =G87+L87+M87 -> 0 | O87: =N87*D87 -> 0 | P87: =T87/D87 -> 220 | Q87: 0 | S87: 0 | T87: 199980 | U87: =O87/T87 -> 0
A88: =VLOOKUP(B88,Grupos!$A$2:$B$619,2,FALSE) -> INTERIORES | B88: I12P | C88: INTERIOR 12 CTOS 2F 125 AMP | D88: 2 | E88: 15453.34 | F88: 935.42 | G88: =E88+F88 -> 16388.76 | H88: =E88*D88 -> 30906.68 | I88: =F88*D88 -> 1870.84 | J88: =G88*D88 -> 32777.52 | K88: =J88/$J$264 -> 2.462632e-05 | L88: 3185.4013 | M88: 5023.5137 | N88: =G88+L88+M88 -> 24597.675 | O88: =N88*D88 -> 49195.35 | P88: =T88/D88 -> 64828 | Q88: 170600 | R88: =Q88-P88 -> 105772 | S88: =R88/Q88 -> 0.62 | T88: 129656 | U88: =O88/T88 -> 0.3794298
A89: =VLOOKUP(B89,Grupos!$A$2:$B$619,2,FALSE) -> INTERIORES | B89: I18P | C89: INTERIOR 18 CTOS 2F 125 AMP | D89: 8 | E89: 21969.01 | F89: 1049.78 | G89: =E89+F89 -> 23018.79 | H89: =E89*D89 -> 175752.08 | I89: =F89*D89 -> 8398.24 | J89: =G89*D89 -> 184150.32 | K89: =J89/$J$264 -> 0.00013835534 | L89: 4474.0471 | M89: 5637.6645 | N89: =G89+L89+M89 -> 33130.502 | O89: =N89*D89 -> 265044.01 | P89: =T89/D89 -> 83220 | Q89: 219000 | R89: =Q89-P89 -> 135780 | S89: =R89/Q89 -> 0.62 | T89: 665760 | U89: =O89/T89 -> 0.39810745
A90: =VLOOKUP(B90,Grupos!$A$2:$B$619,2,FALSE) -> INTERIORES | B90: I224 | C90: INTERIOR 24 CTOS 2F 225 AMP | D90: 2 | E90: 39787.73 | F90: 2660.46 | G90: =E90+F90 -> 42448.19 | H90: =E90*D90 -> 79575.46 | I90: =F90*D90 -> 5320.92 | J90: =G90*D90 -> 84896.38 | K90: =J90/$J$264 -> 6.3784126e-05 | L90: 8250.4424 | M90: 14287.547 | N90: =G90+L90+M90 -> 64986.179 | O90: =N90*D90 -> 129972.36 | P90: =T90/D90 -> 143963 | Q90: 378850 | R90: =Q90-P90 -> 234887 | S90: =R90/Q90 -> 0.62 | T90: 287926 | U90: =O90/T90 -> 0.4514089
A91: =VLOOKUP(B91,Grupos!$A$2:$B$619,2,FALSE) -> INTERIORES | B91: I230 | C91: INTERIOR 30 CTOS 2F 225 AMP | D91: 3 | E91: 49797.97 | F91: 2108.2 | G91: =E91+F91 -> 51906.17 | H91: =E91*D91 -> 149393.91 | I91: =F91*D91 -> 6324.6 | J91: =G91*D91 -> 155718.51 | K91: =J91/$J$264 -> 0.00011699402 | L91: 10088.743 | M91: 11321.729 | N91: =G91+L91+M91 -> 73316.641 | O91: =N91*D91 -> 219949.92 | P91: =T91/D91 -> 184000 | Q91: 480000 | R91: =Q91-P91 -> 296000 | S91: =R91/Q91 -> 0.61666667 | T91: 551999.99 | U91: =O91/T91 -> 0.39846001
A92: =VLOOKUP(B92,Grupos!$A$2:$B$619,2,FALSE) -> INTERIORES | B92: I312 | C92: INTERIOR 12 CTOS 3F 225 AMP | D92: 34 | E92: 25206.92 | F92: 1511.1 | G92: =E92+F92 -> 26718.02 | H92: =E92*D92 -> 857035.28 | I92: =F92*D92 -> 51377.4 | J92: =G92*D92 -> 908412.68 | K92: =J92/$J$264 -> 0.00068250624 | L92: 5193.0479 | M92: 8115.105 | N92: =G92+L92+M92 -> 40026.173 | O92: =N92*D92 -> 1360889.9 | P92: =T92/D92 -> 98693.088 | Q92: 256150 | R92: =Q92-P92 -> 157456.91 | S92: =R92/Q92 -> 0.61470588 | T92: 3355565 | U92: =O92/T92 -> 0.40556207
A93: =VLOOKUP(B93,Grupos!$A$2:$B$619,2,FALSE) -> INTERIORES | B93: I318 | C93: INTERIOR 18 CTOS 3F 225 AMP | D93: 13 | E93: 37165.5 | F93: 2067.14 | G93: =E93+F93 -> 39232.64 | H93: =E93*D93 -> 483151.5 | I93: =F93*D93 -> 26872.82 | J93: =G93*D93 -> 510024.32 | K93: =J93/$J$264 -> 0.00038319014 | L93: 7625.452 | M93: 11101.223 | N93: =G93+L93+M93 -> 57959.315 | O93: =N93*D93 -> 753471.09 | P93: =T93/D93 -> 119073 | Q93: 313350 | R93: =Q93-P93 -> 194277 | S93: =R93/Q93 -> 0.62 | T93: 1547949 | U93: =O93/T93 -> 0.48675448
A94: =VLOOKUP(B94,Grupos!$A$2:$B$619,2,FALSE) -> INTERIORES | B94: I318-125 | C94: INTERIOR 18 CTOS 3F 125 AMP | D94: 2 | E94: 30107.38 | F94: 1595.87 | G94: =E94+F94 -> 31703.25 | H94: =E94*D94 -> 60214.76 | I94: =F94*D94 -> 3191.74 | J94: =G94*D94 -> 63406.5 | K94: =J94/$J$264 -> 4.7638406e-05 | L94: 6162.0021 | M94: 8570.3478 | N94: =G94+L94+M94 -> 46435.6 | O94: =N94*D94 -> 92871.2 | P94: =T94/D94 -> 109472 | Q94: 248800 | R94: =Q94-P94 -> 139328 | S94: =R94/Q94 -> 0.56 | T94: 218944 | U94: =O94/T94 -> 0.42417787
A95: =VLOOKUP(B95,Grupos!$A$2:$B$619,2,FALSE) -> INTERIORES | B95: I318-BIMETALICO | C95: INTERIOR 18 CTOS 3 FASES TRP318 BIMETALICO | D95: 7 | E95: 12022 | F95: 2049.66 | G95: =E95+F95 -> 14071.66 | H95: =E95*D95 -> 84154 | I95: =F95*D95 -> 14347.62 | J95: =G95*D95 -> 98501.62 | K95: =J95/$J$264 -> 7.4005979e-05 | L95: 2735.0382 | M95: 11007.35 | N95: =G95+L95+M95 -> 27814.048 | O95: =N95*D95 -> 194698.33 | P95: =T95/D95 -> 102008.01 | Q95: 248800 | R95: =Q95-P95 -> 146791.99 | S95: =R95/Q95 -> 0.58999997 | T95: 714056.05 | U95: =O95/T95 -> 0.27266534
A96: =VLOOKUP(B96,Grupos!$A$2:$B$619,2,FALSE) -> INTERIORES | B96: I324 | C96: INTERIOR 24 CTOS 3F 225 AMP | D96: 1 | E96: 49135.39 | F96: 2558.08 | G96: =E96+F96 -> 51693.47 | H96: =E96*D96 -> 49135.39 | I96: =F96*D96 -> 2558.08 | J96: =G96*D96 -> 51693.47 | K96: =J96/$J$264 -> 3.8838203e-05 | L96: 10047.401 | M96: 13737.733 | N96: =G96+L96+M96 -> 75478.604 | O96: =N96*D96 -> 75478.604 | P96: =T96/D96 -> 178059.51 | Q96: 378850 | R96: =Q96-P96 -> 200790.49 | S96: =R96/Q96 -> 0.52999997 | T96: 178059.51 | U96: =O96/T96 -> 0.42389538
...

Sheet Feb
A2: DETALLE DE VENTAS 2026
E3: COSTO SIT UNITARIO | H3: COSTO SIT CANTIDAD
A4: GRUPO | B4: REF. | C4: DESCRIPCION | D4: CANT | E4: CUMAT | F4: CUMO | G4: CUNago | H4: CTMAT | I4: CTMO | J4: CTSIT | K4: %PART | L4: CIFU | M4: MOU | N4: CTU | O4: CT | P4: PUV | Q4: PRECIOTOT | R4: %CTO | S4: %Part. | T4: MO Nago | U4: Dif | W4: MP Nago | X4: Dif
A5: =VLOOKUP(B5,Grupos!$A$2:$B$619,2,FALSE) -> ACCESORIOS | B5: 997 | C5: MAYOR VALOR COBRADO | D5: -2 | E5: 0 | F5: 0 | G5: =E5+F5 -> 0 | H5: =E5*D5 -> 0 | I5: =F5*D5 -> 0 | J5: =G5*D5 -> 0 | K5: =J5/$J$308 -> 0 | L5: =$K$383*K5/D5 -> 0 | M5: =F5*$M$382 -> 0 | N5: =G5+L5+M5 -> 0 | O5: =N5*D5 -> 0 | P5: =Q5/D5 -> 737800 | Q5: =-1404327-71273 -> -1475600 | R5: =O5/Q5 -> 0 | T5: =IFERROR(VLOOKUP(B5,[1]Todos!$A$2:$C$3021,3,FALSE),0) -> 0 | U5: =T5-F5 -> 0 | W5: =IFERROR(VLOOKUP(B5,[1]Todos!$A$2:$B$3021,2,FALSE),0) -> 0 | X5: =W5-E5 -> 0
A6: =VLOOKUP(B6,Grupos!$A$2:$B$619,2,FALSE) -> ACCESORIOS | B6: BN-08 | C6: BANDEJA PARA INTERIOR *I-8P* | D6: 1 | E6: 1216.9 | F6: 73.14 | G6: =E6+F6 -> 1290.04 | H6: =E6*D6 -> 1216.9 | I6: =F6*D6 -> 73.14 | J6: =G6*D6 -> 1290.04 | K6: =J6/$J$308 -> 7.6982246e-07 | L6: =$K$383*K6/D6 -> 321.15813 | M6: =F6*$M$382 -> 430.37216 | N6: =G6+L6+M6 -> 2041.5703 | O6: =N6*D6 -> 2041.5703 | P6: =Q6/D6 -> 6762 | Q6: 6762 | R6: =O6/Q6 -> 0.30191811 | T6: =IFERROR(VLOOKUP(B6,[1]Todos!$A$2:$C$3021,3,FALSE),0) -> 0 | U6: =T6-F6 -> -73.14 | W6: =IFERROR(VLOOKUP(B6,[1]Todos!$A$2:$B$3021,2,FALSE),0) -> 0 | X6: =W6-E6 -> -1216.9
A7: =VLOOKUP(B7,Grupos!$A$2:$B$619,2,FALSE) -> ACCESORIOS | B7: BN-18 | C7: BANDEJA PARA INTERIOR *I-18P,I-218,I-318 | D7: 1 | E7: 2120.5 | F7: 123.35 | G7: =E7+F7 -> 2243.85 | H7: =E7*D7 -> 2120.5 | I7: =F7*D7 -> 123.35 | J7: =G7*D7 -> 2243.85 | K7: =J7/$J$308 -> 1.339002e-06 | L7: =$K$383*K7/D7 -> 558.61111 | M7: =F7*$M$382 -> 725.81906 | N7: =G7+L7+M7 -> 3528.2802 | O7: =N7*D7 -> 3528.2802 | P7: =Q7/D7 -> 11970 | Q7: 11970 | R7: =O7/Q7 -> 0.29476025 | T7: =IFERROR(VLOOKUP(B7,[1]Todos!$A$2:$C$3021,3,FALSE),0) -> 0 | U7: =T7-F7 -> -123.35 | W7: =IFERROR(VLOOKUP(B7,[1]Todos!$A$2:$B$3021,2,FALSE),0) -> 0 | X7: =W7-E7 -> -2120.5
A8: =VLOOKUP(B8,Grupos!$A$2:$B$619,2,FALSE) -> ACCESORIOS | B8: BN-24 | C8: BANDEJA PARA INTERIOR *I-224,I-324* | D8: 1 | E8: 2376.63 | F8: 87.07 | G8: =E8+F8 -> 2463.7 | H8: =E8*D8 -> 2376.63 | I8: =F8*D8 -> 87.07 | J8: =G8*D8 -> 2463.7 | K8: =J8/$J$308 -> 1.470196e-06 | L8: =$K$383*K8/D8 -> 613.34322 | M8: =F8*$M$382 -> 512.3394 | N8: =G8+L8+M8 -> 3589.3826 | O8: =N8*D8 -> 3589.3826 | P8: =Q8/D8 -> 26700 | Q8: 26700 | R8: =O8/Q8 -> 0.13443381 | T8: =IFERROR(VLOOKUP(B8,[1]Todos!$A$2:$C$3021,3,FALSE),0) -> 0 | U8: =T8-F8 -> -87.07 | W8: =IFERROR(VLOOKUP(B8,[1]Todos!$A$2:$B$3021,2,FALSE),0) -> 0 | X8: =W8-E8 -> -2376.63
A9: =VLOOKUP(B9,Grupos!$A$2:$B$619,2,FALSE) -> ACCESORIOS | B9: BN-36 | C9: BANDEJA PARA INTERIOR *I-236,I-336* | D9: 1 | E9: 3286.26 | F9: 157.35 | G9: =E9+F9 -> 3443.61 | H9: =E9*D9 -> 3286.26 | I9: =F9*D9 -> 157.35 | J9: =G9*D9 -> 3443.61 | K9: =J9/$J$308 -> 2.0549505e-06 | L9: =$K$383*K9/D9 -> 857.29384 | M9: =F9*$M$382 -> 925.88268 | N9: =G9+L9+M9 -> 5226.7865 | O9: =N9*D9 -> 5226.7865 | P9: =Q9/D9 -> 38587.5 | Q9: 38587.5 | R9: =O9/Q9 -> 0.13545284 | T9: =IFERROR(VLOOKUP(B9,[1]Todos!$A$2:$C$3021,3,FALSE),0) -> 0 | U9: =T9-F9 -> -157.35 | W9: =IFERROR(VLOOKUP(B9,[1]Todos!$A$2:$B$3021,2,FALSE),0) -> 0 | X9: =W9-E9 -> -3286.26
A10: =VLOOKUP(B10,Grupos!$A$2:$B$619,2,FALSE) -> ACCESORIOS | B10: BNTOTA | C10: BANDEJA PARA TOTALIZADOR | D10: 1 | E10: 2141.58 | F10: 66.96 | G10: =E10+F10 -> 2208.54 | H10: =E10*D10 -> 2141.58 | I10: =F10*D10 -> 66.96 | J10: =G10*D10 -> 2208.54 | K10: =J10/$J$308 -> 1.317931e-06 | L10: =$K$383*K10/D10 -> 549.82061 | M10: =F10*$M$382 -> 394.00766 | N10: =G10+L10+M10 -> 3152.3683 | O10: =N10*D10 -> 3152.3683 | P10: =Q10/D10 -> 33112.5 | Q10: 33112.5 | R10: =O10/Q10 -> 0.09520176 | T10: =IFERROR(VLOOKUP(B10,[1]Todos!$A$2:$C$3021,3,FALSE),0) -> 67 | U10: =T10-F10 -> 0.04 | W10: =IFERROR(VLOOKUP(B10,[1]Todos!$A$2:$B$3021,2,FALSE),0) -> 1927.16 | X10: =W10-E10 -> -214.42
A11: =VLOOKUP(B11,Grupos!$A$2:$B$619,2,FALSE) -> ACCESORIOS | B11: CHAPA-1 | C11: CHAPA GAVETA (TRPs) | D11: 20 | E11: 3200 | F11: 0 | G11: =E11+F11 -> 3200 | H11: =E11*D11 -> 64000 | I11: =F11*D11 -> 0 | J11: =G11*D11 -> 64000 | K11: =J11/$J$308 -> 3.8191558e-05 | L11: =$K$383*K11/D11 -> 796.64663 | M11: =F11*$M$382 -> 0 | N11: =G11+L11+M11 -> 3996.6466 | O11: =N11*D11 -> 79932.933 | P11: =Q11/D11 -> 7217.55 | Q11: 144351 | R11: =O11/Q11 -> 0.55374007 | T11: =IFERROR(VLOOKUP(B11,[1]Todos!$A$2:$C$3021,3,FALSE),0) -> 0 | U11: =T11-F11 -> 0 | W11: =IFERROR(VLOOKUP(B11,[1]Todos!$A$2:$B$3021,2,FALSE),0) -> 3200 | X11: =W11-E11 -> 0
A12: =VLOOKUP(B12,Grupos!$A$2:$B$619,2,FALSE) -> ACCESORIOS | B12: CIERRE | C12: CIERRE DE TRINQUETE | D12: 20 | E12: 68.22 | F12: 12.44 | G12: =E12+F12 -> 80.66 | H12: =E12*D12 -> 1364.4 | I12: =F12*D12 -> 248.8 | J12: =G12*D12 -> 1613.2 | K12: =J12/$J$308 -> 9.6266596e-07 | L12: =$K$383*K12/D12 -> 20.080474 | M12: =F12*$M$382 -> 73.19975 | N12: =G12+L12+M12 -> 173.94022 | O12: =N12*D12 -> 3478.8045 | P12: =Q12/D12 -> 1540 | Q12: 30800 | R12: =O12/Q12 -> 0.1129482 | T12: =IFERROR(VLOOKUP(B12,[1]Todos!$A$2:$C$3021,3,FALSE),0) -> 12.51 | U12: =T12-F12 -> 0.07 | W12: =IFERROR(VLOOKUP(B12,[1]Todos!$A$2:$B$3021,2,FALSE),0) -> 68.15 | X12: =W12-E12 -> -0.07
A13: =VLOOKUP(B13,Grupos!$A$2:$B$619,2,FALSE) -> ACCESORIOS | B13: FLETES | C13: VALOR FLETES MERCANCIA | D13: 2 | E13: 0 | F13: 0 | G13: =E13+F13 -> 0 | H13: =E13*D13 -> 0 | I13: =F13*D13 -> 0 | J13: =G13*D13 -> 0 | K13: =J13/$J$308 -> 0 | L13: =$K$383*K13/D13 -> 0 | M13: =F13*$M$382 -> 0 | N13: =G13+L13+M13 -> 0 | O13: =N13*D13 -> 0 | P13: =Q13/D13 -> 351000 | Q13: 702000 | R13: =O13/Q13 -> 0 | T13: =IFERROR(VLOOKUP(B13,[1]Todos!$A$2:$C$3021,3,FALSE),0) -> 0 | U13: =T13-F13 -> 0 | W13: =IFERROR(VLOOKUP(B13,[1]Todos!$A$2:$B$3021,2,FALSE),0) -> 0 | X13: =W13-E13 -> 0
A14: =VLOOKUP(B14,Grupos!$A$2:$B$619,2,FALSE) -> ACCESORIOS | B14: GRAPAM12-D | C14: GRAPA METALICA 1/2" DOBLE | D14: 13800 | E14: 59.89 | F14: 35.07 | G14: =E14+F14 -> 94.96 | H14: =E14*D14 -> 826482 | I14: =F14*D14 -> 483966 | J14: =G14*D14 -> 1310448 | K14: =J14/$J$308 -> 0.00078200079 | L14: =$K$383*K14/D14 -> 23.640489 | M14: =F14*$M$382 -> 206.35974 | N14: =G14+L14+M14 -> 324.96023 | O14: =N14*D14 -> 4484451.2 | P14: =Q14/D14 -> 120.3913 | Q14: 1661399.9 | R14: =O14/Q14 -> 2.6992003 | T14: =IFERROR(VLOOKUP(B14,[1]Todos!$A$2:$C$3021,3,FALSE),0) -> 29.35 | U14: =T14-F14 -> -5.72 | W14: =IFERROR(VLOOKUP(B14,[1]Todos!$A$2:$B$3021,2,FALSE),0) -> 55.77 | X14: =W14-E14 -> -4.12
A15: =VLOOKUP(B15,Grupos!$A$2:$B$619,2,FALSE) -> ACCESORIOS | B15: GRAPAM12-S | C15: GRAPA METALICA 1/2" SENCILLA | D15: -2400 | E15: 43.39 | F15: 43.22 | G15: =E15+F15 -> 86.61 | H15: =E15*D15 -> -104136 | I15: =F15*D15 -> -103728 | J15: =G15*D15 -> -207864 | K15: =J15/$J$308 -> -0.00012404141 | L15: =$K$383*K15/D15 -> 21.561739 | M15: =F15*$M$382 -> 254.31617 | N15: =G15+L15+M15 -> 362.48791 | O15: =N15*D15 -> -869970.99 | P15: =Q15/D15 -> 102.50001 | Q15: -246000.02 | R15: =O15/Q15 -> 3.5364671 | T15: =IFERROR(VLOOKUP(B15,[1]Todos!$A$2:$C$3021,3,FALSE),0) -> 44.51 | U15: =T15-F15 -> 1.29 | W15: =IFERROR(VLOOKUP(B15,[1]Todos!$A$2:$B$3021,2,FALSE),0) -> 40.38 | X15: =W15-E15 -> -3.01
A16: =VLOOKUP(B16,Grupos!$A$2:$B$619,2,FALSE) -> ACCESORIOS | B16: NEUTRO12 | C16: NEUTRO DE 12 CIRCUITOS | D16: 28 | E16: 2166.94 | F16: 0 | G16: =E16+F16 -> 2166.94 | H16: =E16*D16 -> 60674.32 | I16: =F16*D16 -> 0 | J16: =G16*D16 -> 60674.32 | K16: =J16/$J$308 -> 3.6206981e-05 | L16: =$K$383*K16/D16 -> 539.4642 | M16: =F16*$M$382 -> 0 | N16: =G16+L16+M16 -> 2706.4042 | O16: =N16*D16 -> 75779.318 | P16: =Q16/D16 -> 12970.286 | Q16: 363168 | R16: =O16/Q16 -> 0.20866188 | T16: =IFERROR(VLOOKUP(B16,[1]Todos!$A$2:$C$3021,3,FALSE),0) -> 0 | U16: =T16-F16 -> 0 | W16: =IFERROR(VLOOKUP(B16,[1]Todos!$A$2:$B$3021,2,FALSE),0) -> 2166.94 | X16: =W16-E16 -> 0
A17: =VLOOKUP(B17,Grupos!$A$2:$B$619,2,FALSE) -> ACCESORIOS | B17: NEUTRO18 | C17: NEUTRO DE 18 CIRCUITOS | D17: 1 | E17: 3042.06 | F17: 0 | G17: =E17+F17 -> 3042.06 | H17: =E17*D17 -> 3042.06 | I17: =F17*D17 -> 0 | J17: =G17*D17 -> 3042.06 | K17: =J17/$J$308 -> 1.8153283e-06 | L17: =$K$383*K17/D17 -> 757.32714 | M17: =F17*$M$382 -> 0 | N17: =G17+L17+M17 -> 3799.3871 | O17: =N17*D17 -> 3799.3871 | P17: =Q17/D17 -> 32812.5 | Q17: 32812.5 | R17: =O17/Q17 -> 0.11579085 | T17: =IFERROR(VLOOKUP(B17,[1]Todos!$A$2:$C$3021,3,FALSE),0) -> 0 | U17: =T17-F17 -> 0 | W17: =IFERROR(VLOOKUP(B17,[1]Todos!$A$2:$B$3021,2,FALSE),0) -> 3042.06 | X17: =W17-E17 -> 0
... A42: =VLOOKUP(B42,Grupos!$A$2:$B$619,2,FALSE) -> ACCESORIOS | B42: TIERRA8 | C42: TIERRA DE 8 CIRCUITOS | D42: 136 | E42: 1666.74 | F42: 0 | G42: =E42+F42 -> 1666.74 | H42: =E42*D42 -> 226676.64 | I42: =F42*D42 -> 0 | J42: =G42*D42 -> 226676.64 | K42: =J42/$J$308 -> 0.00013526772 | L42: =$K$383*K42/D42 -> 414.93838 | M42: =F42*$M$382 -> 0 | N42: =G42+L42+M42 -> 2081.6784 | O42: =N42*D42 -> 283108.26 | P42: =Q42/D42 -> 9227.0591 | Q42: 1254880 | R42: =O42/Q42 -> 0.22560583 | T42: =IFERROR(VLOOKUP(B42,[1]Todos!$A$2:$C$3021,3,FALSE),0) -> 0 | U42: =T42-F42 -> 0 | W42: =IFERROR(VLOOKUP(B42,[1]Todos!$A$2:$B$3021,2,FALSE),0) -> 1666.74 | X42: =W42-E42 -> 0
A43: Total ACCESORIOS | D43: =SUBTOTAL(9,D5:D42) -> 13349 | H43: =SUBTOTAL(9,H5:H42) -> 2145861.2 | I43: =SUBTOTAL(9,I5:I42) -> 418308.47 | J43: =SUBTOTAL(9,J5:J42) -> 2564169.7 | O43: =SUBTOTAL(9,O5:O42) -> 5663945.8 | Q43: =SUBTOTAL(9,Q5:Q42) -> 8687211.6 | R43: =O43/Q43 -> 0.65198663 | S43: =Q43/$Q$308 -> 0.0020062368 | T43: =IFERROR(VLOOKUP(B43,[1]Todos!$A$2:$C$3021,3,FALSE),0) -> 0 | U43: =T43-F43 -> 0 | W43: =IFERROR(VLOOKUP(B43,[1]Todos!$A$2:$B$3021,2,FALSE),0) -> 0 | X43: =W43-E43 -> 0
A44: =VLOOKUP(B44,Grupos!$A$2:$B$619,2,FALSE) -> ADAPTADORES | B44: ACAMPANA12 | C44: ADAPTADOR CAMPANA 1/2" | D44: 12794 | E44: 15.04 | F44: 4.89 | G44: =E44+F44 -> 19.93 | H44: =E44*D44 -> 192421.76 | I44: =F44*D44 -> 62562.66 | J44: =G44*D44 -> 254984.42 | K44: =J44/$J$308 -> 0.00015216019 | L44: =$K$383*K44/D44 -> 4.9616148 | M44: =F44*$M$382 -> 28.773857 | N44: =G44+L44+M44 -> 53.665471 | O44: =N44*D44 -> 686596.04 | P44: =Q44/D44 -> 87.187358 | Q44: 1115475.1 | R44: =O44/Q44 -> 0.61551895 | T44: =IFERROR(VLOOKUP(B44,[1]Todos!$A$2:$C$3021,3,FALSE),0) -> 4.85 | U44: =T44-F44 -> -0.04 | W44: =IFERROR(VLOOKUP(B44,[1]Todos!$A$2:$B$3021,2,FALSE),0) -> 15.04 | X44: =W44-E44 -> 0
A45: =VLOOKUP(B45,Grupos!$A$2:$B$619,2,FALSE) -> ADAPTADORES | B45: ACAMPANA34 | C45: ADAPTADOR CAMPANA 3/4" | D45: 3000 | E45: 20.18 | F45: 5.27 | G45: =E45+F45 -> 25.45 | H45: =E45*D45 -> 60540 | I45: =F45*D45 -> 15810 | J45: =G45*D45 -> 76350 | K45: =J45/$J$308 -> 4.5561335e-05 | L45: =$K$383*K45/D45 -> 6.3358302 | M45: =F45*$M$382 -> 31.009862 | N45: =G45+L45+M45 -> 62.795692 | O45: =N45*D45 -> 188387.08 | P45: =Q45/D45 -> 104 | Q45: 312000.01 | R45: =O45/Q45 -> 0.60380471 | T45: =IFERROR(VLOOKUP(B45,[1]Todos!$A$2:$C$3021,3,FALSE),0) -> 4.9 | U45: =T45-F45 -> -0.37 | W45: =IFERROR(VLOOKUP(B45,[1]Todos!$A$2:$B$3021,2,FALSE),0) -> 20.18 | X45: =W45-E45 -> 0
A46: =VLOOKUP(B46,Grupos!$A$2:$B$619,2,FALSE) -> ADAPTADORES | B46: ADAPTER12 | C46: ADAPTADOR TERMINAL 1/2" | D46: 648000 | E46: 26.11 | F46: 10.98 | G46: =E46+F46 -> 37.09 | H46: =E46*D46 -> 16919280 | I46: =F46*D46 -> 7115040 | J46: =G46*D46 -> 24034320 | K46: =J46/$J$308 -> 0.014342314 | L46: =$K$383*K46/D46 -> 9.2336323 | M46: =F46*$M$382 -> 64.608782 | N46: =G46+L46+M46 -> 110.93241 | O46: =N46*D46 -> 71884205 | P46: =Q46/D46 -> 107.1 | Q46: 69400803 | R46: =O46/Q46 -> 1.0357835 | T46: =IFERROR(VLOOKUP(B46,[1]Todos!$A$2:$C$3021,3,FALSE),0) -> 10.32 | U46: =T46-F46 -> -0.66 | W46: =IFERROR(VLOOKUP(B46,[1]Todos!$A$2:$B$3021,2,FALSE),0) -> 26.12 | X46: =W46-E46 -> 0.01
A47: =VLOOKUP(B47,Grupos!$A$2:$B$619,2,FALSE) -> ADAPTADORES | B47: ADAPTER12-AI | C47: ADAPTADOR TERMINAL 1/2" ALTO IMPACTO | D47: 19200 | E47: 55.65 | F47: 10.16 | G47: =E47+F47 -> 65.81 | H47: =E47*D47 -> 1068480 | I47: =F47*D47 -> 195072 | J47: =G47*D47 -> 1263552 | K47: =J47/$J$308 -> 0.00075401593 | L47: =$K$383*K47/D47 -> 16.383536 | M47: =F47*$M$382 -> 59.783718 | N47: =G47+L47+M47 -> 141.97725 | O47: =N47*D47 -> 2725963.3 | P47: =Q47/D47 -> 175.3125 | Q47: 3365999.9 | R47: =O47/Q47 -> 0.80985245 | T47: =IFERROR(VLOOKUP(B47,[1]Todos!$A$2:$C$3021,3,FALSE),0) -> 10.6 | U47: =T47-F47 -> 0.44 | W47: =IFERROR(VLOOKUP(B47,[1]Todos!$A$2:$B$3021,2,FALSE),0) -> 55.65 | X47: =W47-E47 -> 0
A48: =VLOOKUP(B48,Grupos!$A$2:$B$619,2,FALSE) -> ADAPTADORES | B48: ADAPTER12-PP-SE | C48: ADAPTADOR TERMINAL 1/2" EN POLIPROPILENO SIN ENSAMBLE | D48: 400500 | E48: 27.67 | F48: 6.42 | G48: =E48+F48 -> 34.09 | H48: =E48*D48 -> 11081835 | I48: =F48*D48 -> 2571210 | J48: =G48*D48 -> 13653045 | K48: =J48/$J$308 -> 0.0081473603 | L48: =$K$383*K48/D48 -> 8.4867761 | M48: =F48*$M$382 -> 37.77672 | N48: =G48+L48+M48 -> 80.353496 | O48: =N48*D48 -> 32181575 | P48: =Q48/D48 -> 105.45843 | Q48: 42236101 | R48: =O48/Q48 -> 0.76194473 | T48: =IFERROR(VLOOKUP(B48,[1]Todos!$A$2:$C$3021,3,FALSE),0) -> 5.37 | U48: =T48-F48 -> -1.05 | W48: =IFERROR(VLOOKUP(B48,[1]Todos!$A$2:$B$3021,2,FALSE),0) -> 27.67 | X48: =W48-E48 -> 0
A49: =VLOOKUP(B49,Grupos!$A$2:$B$619,2,FALSE) -> ADAPTADORES | B49: ADAPTER34 | C49: ADAPTADOR TERMINAL 3/4" | D49: 290400 | E49: 40.16 | F49: 11.35 | G49: =E49+F49 -> 51.51 | H49: =E49*D49 -> 11662464 | I49: =F49*D49 -> 3296040 | J49: =G49*D49 -> 14958504 | K49: =J49/$J$308 -> 0.0089263839 | L49: =$K$383*K49/D49 -> 12.823521 | M49: =F49*$M$382 -> 66.785945 | N49: =G49+L49+M49 -> 131.11947 | O49: =N49*D49 -> 38077093 | P49: =Q49/D49 -> 143.33885 | Q49: 41625601 | R49: =O49/Q49 -> 0.91475179 | T49: =IFERROR(VLOOKUP(B49,[1]Todos!$A$2:$C$3021,3,FALSE),0) -> 11.11 | U49: =T49-F49 -> -0.24 | W49: =IFERROR(VLOOKUP(B49,[1]Todos!$A$2:$B$3021,2,FALSE),0) -> 41.81 | X49: =W49-E49 -> 1.65
A50: Total ADAPTADORES | D50: =SUBTOTAL(9,D44:D49) -> 1373894 | H50: =SUBTOTAL(9,H44:H49) -> 40985021 | I50: =SUBTOTAL(9,I44:I49) -> 13255735 | J50: =SUBTOTAL(9,J44:J49) -> 54240755 | O50: =SUBTOTAL(9,O44:O49) -> 1.4574382e+08 | Q50: =SUBTOTAL(9,Q44:Q49) -> 1.5805598e+08 | R50: =O50/Q50 -> 0.92210253 | S50: =Q50/$Q$308 -> 0.036501669 | T50: =IFERROR(VLOOKUP(B50,[1]Todos!$A$2:$C$3021,3,FALSE),0) -> 0 | U50: =T50-F50 -> 0 | W50: =IFERROR(VLOOKUP(B50,[1]Todos!$A$2:$B$3021,2,FALSE),0) -> 0 | X50: =W50-E50 -> 0
A51: =VLOOKUP(B51,Grupos!$A$2:$B$619,2,FALSE) -> CAJAS ARRANCADORAS | B51: CA-30 | C51: CAJA ARRANCADOR Y CONTROL INDUSTRIAL 30X20X16 | D51: 141 | E51: 30398.83 | F51: 4472.47 | G51: =E51+F51 -> 34871.3 | H51: =E51*D51 -> 4286235 | I51: =F51*D51 -> 630618.27 | J51: =G51*D51 -> 4916853.3 | K51: =J51/$J$308 -> 0.0029340982 | L51: =$K$383*K51/D51 -> 8681.2824 | M51: =F51*$M$382 -> 26317.016 | N51: =G51+L51+M51 -> 69869.599 | O51: =N51*D51 -> 9851613.4 | P51: =Q51/D51 -> 107461.54 | Q51: 15152077 | R51: =O51/Q51 -> 0.65018236 | T51: =IFERROR(VLOOKUP(B51,[1]Todos!$A$2:$C$3021,3,FALSE),0) -> 4472.47 | U51: =T51-F51 -> 0 | W51: =IFERROR(VLOOKUP(B51,[1]Todos!$A$2:$B$3021,2,FALSE),0) -> 30398.83 | X51: =W51-E51 -> 0
A52: =VLOOKUP(B52,Grupos!$A$2:$B$619,2,FALSE) -> CAJAS ARRANCADORAS | B52: CA-40 | C52: CAJA ARRANCADOR Y CONTROL INDUSTRIAL 40X30X20 | D52: 121 | E52: 40781.56 | F52: 5353.18 | G52: =E52+F52 -> 46134.74 | H52: =E52*D52 -> 4934568.8 | I52: =F52*D52 -> 647734.78 | J52: =G52*D52 -> 5582303.5 | K52: =J52/$J$308 -> 0.0033312011 | L52: =$K$383*K52/D52 -> 11485.339 | M52: =F52*$M$382 -> 31499.312 | N52: =G52+L52+M52 -> 89119.391 | O52: =N52*D52 -> 10783446 | P52: =Q52/D52 -> 150275.77 | Q52: 18183368 | R52: =O52/Q52 -> 0.593039 | T52: =IFERROR(VLOOKUP(B52,[1]Todos!$A$2:$C$3021,3,FALSE),0) -> 5353.18 | U52: =T52-F52 -> 0 | W52: =IFERROR(VLOOKUP(B52,[1]Todos!$A$2:$B$3021,2,FALSE),0) -> 40781.56 | X52: =W52-E52 -> 0
A53: =VLOOKUP(B53,Grupos!$A$2:$B$619,2,FALSE) -> CAJAS ARRANCADORAS | B53: CA-60 | C53: CAJA ARRANCADOR Y CONTROL INDUSTRIAL 60X40X25 | D53: 48 | E53: 62538.51 | F53: 5265.73 | G53: =E53+F53 -> 67804.24 | H53: =E53*D53 -> 3001848.5 | I53: =F53*D53 -> 252755.04 | J53: =G53*D53 -> 3254603.5 | K53: =J53/$J$308 -> 0.0019421622 | L53: =$K$383*K53/D53 -> 16880.006 | M53: =F53*$M$382 -> 30984.736 | N53: =G53+L53+M53 -> 115668.98 | O53: =N53*D53 -> 5552111.1 | P53: =Q53/D53 -> 247574.08 | Q53: 11883556 | R53: =O53/Q53 -> 0.46720957 | T53: =IFERROR(VLOOKUP(B53,[1]Todos!$A$2:$C$3021,3,FALSE),0) -> 5265.73 | U53: =T53-F53 -> 0 | W53: =IFERROR(VLOOKUP(B53,[1]Todos!$A$2:$B$3021,2,FALSE),0) -> 62538.51 | X53: =W53-E53 -> 0
A54: =VLOOKUP(B54,Grupos!$A$2:$B$619,2,FALSE) -> CAJAS ARRANCADORAS | B54: CA-70 | C54: CAJA ARRANCADOR Y CONTROL INDUSTRIAL 70X50X25 | D54: 20 | E54: 78390.9 | F54: 7236.18 | G54: =E54+F54 -> 85627.08 | H54: =E54*D54 -> 1567818 | I54: =F54*D54 -> 144723.6 | J54: =G54*D54 -> 1712541.6 | K54: =J54/$J$308 -> 0.0010219474 | L54: =$K$383*K54/D54 -> 21317.039 | M54: =F54*$M$382 -> 42579.306 | N54: =G54+L54+M54 -> 149523.42 | O54: =N54*D54 -> 2990468.5 | P54: =Q54/D54 -> 302535.4 | Q54: 6050708 | R54: =O54/Q54 -> 0.49423447 | T54: =IFERROR(VLOOKUP(B54,[1]Todos!$A$2:$C$3021,3,FALSE),0) -> 7236.18 | U54: =T54-F54 -> 0 | W54: =IFERROR(VLOOKUP(B54,[1]Todos!$A$2:$B$3021,2,FALSE),0) -> 78390.9 | X54: =W54-E54 -> 0
A55: =VLOOKUP(B55,Grupos!$A$2:$B$619,2,FALSE) -> CAJAS ARRANCADORAS | B55: CA-80 | C55: CAJA ARRANCADOR Y CONTROL INDUSTRIAL 80X50X25 | D55: 6 | E55: 84343.91 | F55: 8005.49 | G55: =E55+F55 -> 92349.4 | H55: =E55*D55 -> 506063.46 | I55: =F55*D55 -> 48032.94 | J55: =G55*D55 -> 554096.4 | K55: =J55/$J$308 -> 0.0003306532 | L55: =$K$383*K55/D55 -> 22990.574 | M55: =F55*$M$382 -> 47106.098 | N55: =G55+L55+M55 -> 162446.07 | O55: =N55*D55 -> 974676.44 | P55: =Q55/D55 -> 322410.99 | Q55: 1934466 | R55: =O55/Q55 -> 0.50384781 | T55: =IFERROR(VLOOKUP(B55,[1]Todos!$A$2:$C$3021,3,FALSE),0) -> 8005.49 | U55: =T55-F55 -> 0 | W55: =IFERROR(VLOOKUP(B55,[1]Todos!$A$2:$B$3021,2,FALSE),0) -> 84343.91 | X55: =W55-E55 -> 0
A56: =VLOOKUP(B56,Grupos!$A$2:$B$619,2,FALSE) -> CAJAS ARRANCADORAS | B56: CA-90 | C56: CAJA ARRANCADOR Y CONTROL INDUSTRIAL 90X50X25 | D56: 2 | E56: 94916.92 | F56: 5465.68 | G56: =E56+F56 -> 100382.6 | H56: =E56*D56 -> 189833.84 | I56: =F56*D56 -> 10931.36 | J56: =G56*D56 -> 200765.2 | K56: =J56/$J$308 -> 0.00011980525 | L56: =$K$383*K56/D56 -> 24990.456 | M56: =F56*$M$382 -> 32161.287 | N56: =G56+L56+M56 -> 157534.34 | O56: =N56*D56 -> 315068.69 | P56: =Q56/D56 -> 320142.51 | Q56: 640285.01 | R56: =O56/Q56 -> 0.49207569 | T56: =IFERROR(VLOOKUP(B56,[1]Todos!$A$2:$C$3021,3,FALSE),0) -> 5465.68 | U56: =T56-F56 -> 0 | W56: =IFERROR(VLOOKUP(B56,[1]Todos!$A$2:$B$3021,2,FALSE),0) -> 94916.92 | X56: =W56-E56 -> 0
A57: Total CAJAS ARRANCADORAS | D57: =SUBTOTAL(9,D51:D56) -> 338 | H57: =SUBTOTAL(9,H51:H56) -> 14486368 | I57: =SUBTOTAL(9,I51:I56) -> 1734796 | J57: =SUBTOTAL(9,J51:J56) -> 16221164 | O57: =SUBTOTAL(9,O51:O56) -> 30467384 | Q57: =SUBTOTAL(9,Q51:Q56) -> 53844460 | R57: =O57/Q57 -> 0.56584065 | S57: =Q57/$Q$308 -> 0.012434915 | T57: =IFERROR(VLOOKUP(B57,[1]Todos!$A$2:$C$3021,3,FALSE),0) -> 0 | U57: =T57-F57 -> 0 | W57: =IFERROR(VLOOKUP(B57,[1]Todos!$A$2:$B$3021,2,FALSE),0) -> 0 | X57: =W57-E57 -> 0
A58: =VLOOKUP(B58,Grupos!$A$2:$B$619,2,FALSE) -> CAJAS EMPALME | B58: CE13-13-8B | C58: CAJA DE EMPALME 13X13X8 BLANCA | D58: 360 | E58: 2813.7 | F58: 426.22 | G58: =E58+F58 -> 3239.92 | H58: =E58*D58 -> 1012932 | I58: =F58*D58 -> 153439.2 | J58: =G58*D58 -> 1166371.2 | K58: =J58/$J$308 -> 0.00069602396 | L58: =$K$383*K58/D58 -> 806.5848 | M58: =F58*$M$382 -> 2507.9741 | N58: =G58+L58+M58 -> 6554.4789 | O58: =N58*D58 -> 2359612.4 | P58: =Q58/D58 -> 11357.55 | Q58: 4088717.9 | R58: =O58/Q58 -> 0.57710324 | T58: =IFERROR(VLOOKUP(B58,[1]Todos!$A$2:$C$3021,3,FALSE),0) -> 426.22 | U58: =T58-F58 -> 0 | W58: =IFERROR(VLOOKUP(B58,[1]Todos!$A$2:$B$3021,2,FALSE),0) -> 2813.7 | X58: =W58-E58 -> 0
A59: =VLOOKUP(B59,Grupos!$A$2:$B$619,2,FALSE) -> CAJAS EMPALME | B59: CE15-15-10B | C59: CAJA DE EMPALME 15X15X10 BLANCA | D59: 1707 | E59: 3808.35 | F59: 680.53 | G59: =E59+F59 -> 4488.88 | H59: =E59*D59 -> 6500853.5 | I59: =F59*D59 -> 1161664.7 | J59: =G59*D59 -> 7662518.2 | K59: =J59/$J$308 -> 0.0045725548 | L59: =$K$383*K59/D59 -> 1117.516 | M59: =F59*$M$382 -> 4004.3911 | N59: =G59+L59+M59 -> 9610.7871 | O59: =N59*D59 -> 16405614 | P59: =Q59/D59 -> 12991.444 | Q59: 22176396 | R59: =O59/Q59 -> 0.73977818 | T59: =IFERROR(VLOOKUP(B59,[1]Todos!$A$2:$C$3021,3,FALSE),0) -> 680.53 | U59: =T59-F59 -> 0 | W59: =IFERROR(VLOOKUP(B59,[1]Todos!$A$2:$B$3021,2,FALSE),0) -> 3808.35 | X59: =W59-E59 -> 0
A60: =VLOOKUP(B60,Grupos!$A$2:$B$619,2,FALSE) -> CAJAS EMPALME | B60: CE20-15-10B | C60: CAJA DE EMPALME 20X15X10 BLANCA | D60: 220 | E60: 4623.52 | F60: 408.44 | G60: =E60+F60 -> 5031.96 | H60: =E60*D60 -> 1017174.4 | I60: =F60*D60 -> 89856.8 | J60: =G60*D60 -> 1107031.2 | K60: =J60/$J$308 -> 0.00066061322 | L60: =$K$383*K60/D60 -> 1252.7169 | M60: =F60*$M$382 -> 2403.3525 | N60: =G60+L60+M60 -> 8688.0294 | O60: =N60*D60 -> 1911366.5 | P60: =Q60/D60 -> 16041.15 | Q60: 3529053 | R60: =O60/Q60 -> 0.54160889 | T60: =IFERROR(VLOOKUP(B60,[1]Todos!$A$2:$C$3021,3,FALSE),0) -> 408.44 | U60: =T60-F60 -> 0 | W60: =IFERROR(VLOOKUP(B60,[1]Todos!$A$2:$B$3021,2,FALSE),0) -> 4623.52 | X60: =W60-E60 -> 0
A61: =VLOOKUP(B61,Grupos!$A$2:$B$619,2,FALSE) -> CAJAS EMPALME | B61: CE20-20-10B | C61: CAJA DE EMPALME 20X20X10 BLANCA | D61: 2576 | E61: 5549.93 | F61: 701.09 | G61: =E61+F61 -> 6251.02 | H61: =E61*D61 -> 14296620 | I61: =F61*D61 -> 1806007.8 | J61: =G61*D61 -> 16102628 | K61: =J61/$J$308 -> 0.0096091317 | L61: =$K$383*K61/D61 -> 1556.2044 | M61: =F61*$M$382 -> 4125.3708 | N61: =G61+L61+M61 -> 11932.595 | O61: =N61*D61 -> 30738365 | P61: =Q61/D61 -> 18127.31 | Q61: 46695951 | R61: =O61/Q61 -> 0.65826618 | T61: =IFERROR(VLOOKUP(B61,[1]Todos!$A$2:$C$3021,3,FALSE),0) -> 701.09 | U61: =T61-F61 -> 0 | W61: =IFERROR(VLOOKUP(B61,[1]Todos!$A$2:$B$3021,2,FALSE),0) -> 5549.93 | X61: =W61-E61 -> 0
A62: =VLOOKUP(B62,Grupos!$A$2:$B$619,2,FALSE) -> CAJAS EMPALME | B62: CE20-20-15B | C62: CAJA DE EMPALME 20X20X15 BLANCA | D62: 1376 | E62: 6787.81 | F62: 539.74 | G62: =E62+F62 -> 7327.55 | H62: =E62*D62 -> 9340026.6 | I62: =F62*D62 -> 742682.24 | J62: =G62*D62 -> 10082709 | K62: =J62/$J$308 -> 0.0060167868 | L62: =$K$383*K62/D62 -> 1824.2088 | M62: =F62*$M$382 -> 3175.9512 | N62: =G62+L62+M62 -> 12327.71 | O62: =N62*D62 -> 16962929 | P62: =Q62/D62 -> 22835.901 | Q62: 31422199 | R62: =O62/Q62 -> 0.53983901 | T62: =IFERROR(VLOOKUP(B62,[1]Todos!$A$2:$C$3021,3,FALSE),0) -> 539.74 | U62: =T62-F62 -> 0 | W62: =IFERROR(VLOOKUP(B62,[1]Todos!$A$2:$B$3021,2,FALSE),0) -> 6787.81 | X62: =W62-E62 -> 0
A63: =VLOOKUP(B63,Grupos!$A$2:$B$619,2,FALSE) -> CAJAS EMPALME | B63: CE25-20-10B | C63: CAJA DE EMPALME 25X20X10 BLANCA | D63: 216 | E63: 6420.01 | F63: 404.9 | G63: =E63+F63 -> 6824.91 | H63: =E63*D63 -> 1386722.2 | I63: =F63*D63 -> 87458.4 | J63: =G63*D63 -> 1474180.6 | K63: =J63/$J$308 -> 0.00087970707 | L63: =$K$383*K63/D63 -> 1699.0755 | M63: =F63*$M$382 -> 2382.5224 | N63: =G63+L63+M63 -> 10906.508 | O63: =N63*D63 -> 2355805.7 | P63: =Q63/D63 -> 23023.084 | Q63: 4972986.1 | R63: =O63/Q63 -> 0.47372055 | T63: =IFERROR(VLOOKUP(B63,[1]Todos!$A$2:$C$3021,3,FALSE),0) -> 404.9 | U63: =T63-F63 -> 0 | W63: =IFERROR(VLOOKUP(B63,[1]Todos!$A$2:$B$3021,2,FALSE),0) -> 6420.01 | X63: =W63-E63 -> 0
